Workbook
Name HalaqaList: الإعدادات!$C$12:$C$15
Name MaqraaList: الإعدادات!$C$8:$C$9

Sheet الإعدادات
A1: الإعدادات
A2: عدّل الخلايا الصفراء فقط
B3: اسم البرنامج | C3: تعاهد
B4: تاريخ أول جلسة (اختياري)
B5: عدد الأسابيع | C5: 16
B7: المقرأة | C7: الاسم
B8: المقرأة 1 | C8: المقرأة الأولى
B9: المقرأة 2 | C9: المقرأة الثانية
B11: الحلقة | C11: الاسم
B12: الحلقة 1 | C12: ابي بن مالك
B13: الحلقة 2 | C13: ابن رجب
B14: الحلقة 3 | C14: حسان بن ثابت
B15: الحلقة 4 | C15: عبدالرحمن بن النعمان

Sheet طريقة الاستخدام
A1: برنامج تعاهد — ملف المتابعة الأسبوعية
A2: مقرأتان × ٢٠ طالبًا · ٤ حلقات · ١٦ أسبوعًا
B4: ١. الإعدادات | C4: اكتب اسم البرنامج وأسماء المقرأتين والحلقات الأربع، وتاريخ أول جلسة (اختياري) ليظهر تاريخ كل أسبوع.
B5: ٢. الطلاب | C5: اكتب أسماء الطلاب الأربعين، واختر لكل طالب مقرأته وحلقته من القائمة المنسدلة. التوزيع المبدئي: أول ٢٠ طالبًا في المقرأة الأولى والبقية في الثانية، و٥ طلاب من كل حلقة في كل مقرأة.
B6: ٣. الإدخال (أسبوعيًا) | C6: صفوف كل أسبوع متتالية (٤٠ صفًا). استخدم سهم التصفية على عمود «الأسبوع» لعرض أسبوع واحد. عبّئ الخلايا الصفراء فقط: التحضير (حاضر / متأخر / غائب / معتذر)، تقييم الإنجاز من ١٠٠، أوجه الحفظ، أوجه العرض، الأوجه المقروءة.
B7: ٤. التقارير | C7: تُحدَّث تلقائيًا: تقرير كل مقرأة (إنجاز كل طالب في كل أسبوع)، تقرير الحلقات، أفضل ٥ طلاب (اختر الأسبوع في الخلية الصفراء)، وتقرير البرنامج الكامل.
B9: طريقة الحساب
B10: حاضر / متأخر | C10: يُحتسبان حضورًا، ويدخل تقييمهما وأوجههما في التقارير. يظهر عدد المتأخرين منفصلًا.
B11: غائب | C11: تُحتسب نسبة إنجازه صفرًا وتدخل في متوسط المقرأة والحلقة والبرنامج.
B12: معتذر | C12: إذا كُتب له تقييم: تُحتسب نسبة إنجازه حسب تقييمه وتدخل في الإجمالي. وإذا لم يُكتب له تقييم: تُحتسب صفرًا. لا يُعدّ حاضرًا في نسبة الحضور، ويظهر عدد المعتذرين منفصلًا عن الغائبين.
B13: نسبة الإنجاز | C13: مجموع تقييمات الحاضرين والمتأخرين والمعتذرين + صفر لكل غائب ولكل معتذر بلا تقييم، مقسومًا على عددهم، ثم ÷ ١٠٠. الحاضر الذي لم يُكتب له تقييم لا يدخل في المتوسط.
B14: نسبة الحضور | C14: (الحاضرون + المتأخرون) ÷ كل من سُجّل تحضيره في الأسبوع (حاضر، متأخر، غائب، معتذر). الطالب الذي تُرك تحضيره فارغًا لا يُحتسب.
B15: الأوجه | C15: تُجمع أوجه الحفظ والعرض والقراءة للحاضرين والمتأخرين. تقبل أنصاف الأوجه (مثل 1.5).
B16: التقدير | C16: ممتاز ٩٠٪ فأكثر · جيد جدًا ٨٠٪ · جيد ٧٠٪ · مقبول ٦٠٪ · يحتاج متابعة أقل من ٦٠٪.
B17: أفضل ٥ | C17: من الحاضرين والمتأخرين، الترتيب بتقييم الإنجاز، وعند التساوي بأوجه الحفظ ثم أوجه العرض.
B18: في تقرير المقرأة | C18: «غ» غائب (يُحسب صفرًا) · «ع» معتذر بلا تقييم (يُحسب صفرًا) · المعتذر الذي له تقييم تظهر نسبته · الخانة الفارغة = لم يُدخل تقييم.
B20: مفتاح الألوان
B21: خلية صفراء | C21: خلية إدخال: اكتب فيها
B22: خلية رمادية / بيضاء | C22: تُحسب تلقائيًا بالمعادلات: لا تكتب فيها
B24: مثال لصف إدخال (للتوضيح فقط، لا يدخل في الحساب)
B25: الأسبوع | C25: المقرأة | D25: الحلقة | E25: رقم الطالب | F25: اسم الطالب | G25: التحضير | H25: تقييم الإنجاز /100 | I25: أوجه الحفظ | J25: أوجه العرض | K25: الأوجه المقروءة
B26: 3 | C26: المقرأة الأولى | D26: الحلقة الأولى | E26: 7 | F26: عبدالله محمد | G26: متأخر | H26: 92 | I26: 2 | J26: 4 | K26: 10

Sheet الطلاب
A1: الطلاب وتوزيعهم
A4: رقم الطالب | B4: اسم الطالب | C4: المقرأة | D4: الحلقة | E4: مفتاح (تلقائي) | G4: الحلقة | H4: =الإعدادات!$C$8 -> المقرأة الأولى | I4: =الإعدادات!$C$9 -> المقرأة الثانية | J4: المجموع
A5: 1 | B5: غسان اليحيى | C5: =الإعدادات!$C$8 -> المقرأة الأولى | D5: عبدالرحمن بن النعمان | E5: =IF(C5="","",C5&"|"&COUNTIF(C$5:C5,C5)) -> المقرأة الأولى|1 | G5: =الإعدادات!$C$12 -> ابي بن مالك | H5: =COUNTIFS($D$5:$D$44,$G5,$C$5:$C$44,الإعدادات!$C$8) -> 0 | I5: =COUNTIFS($D$5:$D$44,$G5,$C$5:$C$44,الإعدادات!$C$9) -> 9 | J5: =H5+I5 -> 9
A6: 2 | B6: صالح الشريف | C6: =الإعدادات!$C$8 -> المقرأة الأولى | D6: عبدالرحمن بن النعمان | E6: =IF(C6="","",C6&"|"&COUNTIF(C$5:C6,C6)) -> المقرأة الأولى|2 | G6: =الإعدادات!$C$13 -> ابن رجب | H6: =COUNTIFS($D$5:$D$44,$G6,$C$5:$C$44,الإعدادات!$C$8) -> 4 | I6: =COUNTIFS($D$5:$D$44,$G6,$C$5:$C$44,الإعدادات!$C$9) -> 7 | J6: =H6+I6 -> 11
A7: 3 | B7: فهد المشيقح | C7: المقرأة الأولى | D7: عبدالرحمن بن النعمان | E7: =IF(C7="","",C7&"|"&COUNTIF(C$5:C7,C7)) -> المقرأة الأولى|3 | G7: =الإعدادات!$C$14 -> حسان بن ثابت | H7: =COUNTIFS($D$5:$D$44,$G7,$C$5:$C$44,الإعدادات!$C$8) -> 11 | I7: =COUNTIFS($D$5:$D$44,$G7,$C$5:$C$44,الإعدادات!$C$9) -> 0 | J7: =H7+I7 -> 11
A8: 4 | B8: عبدالله الحفير | C8: المقرأة الأولى | D8: عبدالرحمن بن النعمان | E8: =IF(C8="","",C8&"|"&COUNTIF(C$5:C8,C8)) -> المقرأة الأولى|4 | G8: =الإعدادات!$C$15 -> عبدالرحمن بن النعمان | H8: =COUNTIFS($D$5:$D$44,$G8,$C$5:$C$44,الإعدادات!$C$8) -> 6 | I8: =COUNTIFS($D$5:$D$44,$G8,$C$5:$C$44,الإعدادات!$C$9) -> 0 | J8: =H8+I8 -> 6
A9: 5 | B9: زياد الدخيل الله | C9: المقرأة الأولى | D9: عبدالرحمن بن النعمان | E9: =IF(C9="","",C9&"|"&COUNTIF(C$5:C9,C9)) -> المقرأة الأولى|5 | G9: المجموع | H9: =SUM(H5:H8) -> 21 | I9: =SUM(I5:I8) -> 16 | J9: =SUM(J5:J8) -> 37
A10: 6 | B10: عاصم الضبيعي | C10: =الإعدادات!$C$8 -> المقرأة الأولى | D10: =الإعدادات!$C$13 -> ابن رجب | E10: =IF(C10="","",C10&"|"&COUNTIF(C$5:C10,C10)) -> المقرأة الأولى|6
A11: 7 | B11: محمد السعوي | C11: =الإعدادات!$C$8 -> المقرأة الأولى | D11: =الإعدادات!$C$13 -> ابن رجب | E11: =IF(C11="","",C11&"|"&COUNTIF(C$5:C11,C11)) -> المقرأة الأولى|7
A12: 8 | B12: هشام المخلف | C12: =الإعدادات!$C$8 -> المقرأة الأولى | D12: =الإعدادات!$C$13 -> ابن رجب | E12: =IF(C12="","",C12&"|"&COUNTIF(C$5:C12,C12)) -> المقرأة الأولى|8
A13: 9 | B13: اسامة السعدون | C13: =الإعدادات!$C$8 -> المقرأة الأولى | D13: =الإعدادات!$C$13 -> ابن رجب | E13: =IF(C13="","",C13&"|"&COUNTIF(C$5:C13,C13)) -> المقرأة الأولى|9
A14: 10 | B14: محمد الثنيان | C14: =الإعدادات!$C$8 -> المقرأة الأولى | D14: حسان بن ثابت | E14: =IF(C14="","",C14&"|"&COUNTIF(C$5:C14,C14)) -> المقرأة الأولى|10
A15: 11 | B15: كنان الجريفاني | C15: =الإعدادات!$C$8 -> المقرأة الأولى | D15: =الإعدادات!$C$14 -> حسان بن ثابت | E15: =IF(C15="","",C15&"|"&COUNTIF(C$5:C15,C15)) -> المقرأة الأولى|11
A16: 12 | B16: عبدالمجيد الربعي | C16: =الإعدادات!$C$8 -> المقرأة الأولى | D16: =الإعدادات!$C$14 -> حسان بن ثابت | E16: =IF(C16="","",C16&"|"&COUNTIF(C$5:C16,C16)) -> المقرأة الأولى|12
A17: 13 | B17: عبدالله التويجري | C17: =الإعدادات!$C$8 -> المقرأة الأولى | D17: =الإعدادات!$C$14 -> حسان بن ثابت | E17: =IF(C17="","",C17&"|"&COUNTIF(C$5:C17,C17)) -> المقرأة الأولى|13
A18: 14 | B18: حسام التويجري | C18: =الإعدادات!$C$8 -> المقرأة الأولى | D18: =الإعدادات!$C$14 -> حسان بن ثابت | E18: =IF(C18="","",C18&"|"&COUNTIF(C$5:C18,C18)) -> المقرأة الأولى|14
A19: 15 | B19: عبدالرحمن البريدي | C19: =الإعدادات!$C$8 -> المقرأة الأولى | D19: =الإعدادات!$C$14 -> حسان بن ثابت | E19: =IF(C19="","",C19&"|"&COUNTIF(C$5:C19,C19)) -> المقرأة الأولى|15
A20: 16 | B20: عبدالرحمن بازرعة | C20: =الإعدادات!$C$8 -> المقرأة الأولى | D20: حسان بن ثابت | E20: =IF(C20="","",C20&"|"&COUNTIF(C$5:C20,C20)) -> المقرأة الأولى|16
A21: 17 | B21: عبدالله الضحيان | C21: =الإعدادات!$C$8 -> المقرأة الأولى | D21: حسان بن ثابت | E21: =IF(C21="","",C21&"|"&COUNTIF(C$5:C21,C21)) -> المقرأة الأولى|17
A22: 18 | B22: فيصل الدخيل | C22: =الإعدادات!$C$8 -> المقرأة الأولى | D22: حسان بن ثابت | E22: =IF(C22="","",C22&"|"&COUNTIF(C$5:C22,C22)) -> المقرأة الأولى|18
A23: 19 | B23: سليمان المحيميد | C23: =الإعدادات!$C$8 -> المقرأة الأولى | D23: حسان بن ثابت | E23: =IF(C23="","",C23&"|"&COUNTIF(C$5:C23,C23)) -> المقرأة الأولى|19
A24: 20 | B24: اصيل التويجري | C24: المقرأة الثانية | D24: ابن رجب | E24: =IF(C24="","",C24&"|"&COUNTIF(C$5:C24,C24)) -> المقرأة الثانية|1
A25: 21 | B25: جواد الرفيعي | C25: =الإعدادات!$C$9 -> المقرأة الثانية | D25: ابن رجب | E25: =IF(C25="","",C25&"|"&COUNTIF(C$5:C25,C25)) -> المقرأة الثانية|2
A26: 22 | B26: سفيان السبيعي | C26: =الإعدادات!$C$9 -> المقرأة الثانية | D26: ابن رجب | E26: =IF(C27="","",C27&"|"&COUNTIF(C$5:C27,C27)) -> المقرأة الثانية|4
A27: 23 | B27: عمار الفضل | C27: =الإعدادات!$C$9 -> المقرأة الثانية | D27: ابن رجب | E27: =IF(C27="","",C27&"|"&COUNTIF(C$5:C27,C27)) -> المقرأة الثانية|4
A28: 24 | B28: مروان المهوس | C28: =الإعدادات!$C$9 -> المقرأة الثانية | D28: ابن رجب | E28: =IF(C28="","",C28&"|"&COUNTIF(C$5:C28,C28)) -> المقرأة الثانية|5
A29: 25 | B29: جهاد الجدعان | C29: =الإعدادات!$C$9 -> المقرأة الثانية | D29: =الإعدادات!$C$13 -> ابن رجب | E29: =IF(C29="","",C29&"|"&COUNTIF(C$5:C29,C29)) -> المقرأة الثانية|6
A30: 26 | B30: صلاح مسعد | C30: =الإعدادات!$C$9 -> المقرأة الثانية | D30: =الإعدادات!$C$13 -> ابن رجب | E30: =IF(C30="","",C30&"|"&COUNTIF(C$5:C30,C30)) -> المقرأة الثانية|7
A31: 27 | B31: سالم بانوير | C31: =الإعدادات!$C$9 -> المقرأة الثانية | D31: ابي بن مالك | E31: =IF(C31="","",C31&"|"&COUNTIF(C$5:C31,C31)) -> المقرأة الثانية|8
A32: 28 | B32: عبدالعزيز الصقعبي | C32: =الإعدادات!$C$9 -> المقرأة الثانية | D32: ابي بن مالك | E32: =IF(C32="","",C32&"|"&COUNTIF(C$5:C32,C32)) -> المقرأة الثانية|9
A33: 29 | B33: عبدالله المجيدل | C33: =الإعدادات!$C$9 -> المقرأة الثانية | D33: ابي بن مالك | E33: =IF(C33="","",C33&"|"&COUNTIF(C$5:C33,C33)) -> المقرأة الثانية|10
A34: 30 | B34: فواز الشدوخي | C34: =الإعدادات!$C$9 -> المقرأة الثانية | D34: ابي بن مالك | E34: =IF(C34="","",C34&"|"&COUNTIF(C$5:C34,C34)) -> المقرأة الثانية|11
A35: 31 | B35: محمد الطامي | C35: =الإعدادات!$C$9 -> المقرأة الثانية | D35: ابي بن مالك | E35: =IF(C35="","",C35&"|"&COUNTIF(C$5:C35,C35)) -> المقرأة الثانية|12
A36: 32 | B36: مهند الغماس | C36: =الإعدادات!$C$9 -> المقرأة الثانية | D36: ابي بن مالك | E36: =IF(C36="","",C36&"|"&COUNTIF(C$5:C36,C36)) -> المقرأة الثانية|13
A37: 33 | B37: يوسف الحربي | C37: =الإعدادات!$C$9 -> المقرأة الثانية | D37: ابي بن مالك | E37: =IF(C37="","",C37&"|"&COUNTIF(C$5:C37,C37)) -> المقرأة الثانية|14
A38: 34 | B38: عدي الفريح | C38: =الإعدادات!$C$9 -> المقرأة الثانية | D38: ابي بن مالك | E38: =IF(C38="","",C38&"|"&COUNTIF(C$5:C38,C38)) -> المقرأة الثانية|15
A39: 35 | B39: عبدالله الفايزي | C39: المقرأة الثانية | D39: ابي بن مالك | E39: =IF(C39="","",C39&"|"&COUNTIF(C$5:C39,C39)) -> المقرأة الثانية|16
A40: 36 | B40: عزام الحسن | E40: =IF(C40="","",C40&"|"&COUNTIF(C$5:C40,C40))
A41: 37 | B41: أسامة السعوي | C41: المقرأة الأولى | D41: عبدالرحمن بن النعمان | E41: =IF(C41="","",C41&"|"&COUNTIF(C$5:C41,C41)) -> المقرأة الأولى|20
A42: 38 | B42: عاصم الضالع | C42: المقرأة الأولى | D42: حسان بن ثابت | E42: =IF(C42="","",C42&"|"&COUNTIF(C$5:C42,C42)) -> المقرأة الأولى|21
...

Sheet الإدخال
A1: الإدخال الأسبوعي
A4: الأسبوع | B4: المقرأة | C4: الحلقة | D4: رقم الطالب | E4: اسم الطالب | F4: التحضير | G4: تقييم الإنجاز (من 100) | H4: أوجه الحفظ | I4: أوجه العرض | J4: الأوجه المقروءة | L4: ترتيب م1 | M4: ترتيب م2 | N4: حضر | O4: إنجاز محتسب | P4: يُحتسب
A5: 1 | B5: =IFERROR(INDEX(الطلاب!$C$5:$C$44,MATCH($D5,الطلاب!$A$5:$A$44,0)),"") -> المقرأة الأولى | C5: =IFERROR(INDEX(الطلاب!$D$5:$D$44,MATCH($D5,الطلاب!$A$5:$A$44,0)),"") -> عبدالرحمن بن النعمان | D5: 1 | E5: =IFERROR(INDEX(الطلاب!$B$5:$B$44,MATCH($D5,الطلاب!$A$5:$A$44,0)),"") -> غسان اليحيى | F5: حاضر | G5: 85 | H5: 1 | I5: 0 | L5: =IF(AND($A5='أفضل 5 طلاب'!$C$3,$B5=الإعدادات!$C$8,$N5=1,ISNUMBER($G5)),$G5*100000+N($H5)*100+N($I5)+(1000-ROW())/10000,0) -> 0 | M5: =IF(AND($A5='أفضل 5 طلاب'!$C$3,$B5=الإعدادات!$C$9,$N5=1,ISNUMBER($G5)),$G5*100000+N($H5)*100+N($I5)+(1000-ROW())/10000,0) -> 0 | N5: =IF(OR($F5="حاضر",$F5="متأخر"),1,0) -> 1 | O5: =IF(OR($N5=1,$F5="معتذر",$F5="غائب"),IF(ISNUMBER($G5),$G5,IF($N5=1,"",0)),"") -> 85 | P5: =IF(ISNUMBER($O5),1,0) -> 1
A6: 1 | B6: =IFERROR(INDEX(الطلاب!$C$5:$C$44,MATCH($D6,الطلاب!$A$5:$A$44,0)),"") -> المقرأة الأولى | C6: =IFERROR(INDEX(الطلاب!$D$5:$D$44,MATCH($D6,الطلاب!$A$5:$A$44,0)),"") -> عبدالرحمن بن النعمان | D6: 2 | E6: =IFERROR(INDEX(الطلاب!$B$5:$B$44,MATCH($D6,الطلاب!$A$5:$A$44,0)),"") -> صالح الشريف | F6: حاضر | G6: 50 | H6: 0 | I6: 0 | L6: =IF(AND($A6='أفضل 5 طلاب'!$C$3,$B6=الإعدادات!$C$8,$N6=1,ISNUMBER($G6)),$G6*100000+N($H6)*100+N($I6)+(1000-ROW())/10000,0) -> 0 | M6: =IF(AND($A6='أفضل 5 طلاب'!$C$3,$B6=الإعدادات!$C$9,$N6=1,ISNUMBER($G6)),$G6*100000+N($H6)*100+N($I6)+(1000-ROW())/10000,0) -> 0 | N6: =IF(OR($F6="حاضر",$F6="متأخر"),1,0) -> 1 | O6: =IF(OR($N6=1,$F6="معتذر",$F6="غائب"),IF(ISNUMBER($G6),$G6,IF($N6=1,"",0)),"") -> 50 | P6: =IF(ISNUMBER($O6),1,0) -> 1
A7: 1 | B7: =IFERROR(INDEX(الطلاب!$C$5:$C$44,MATCH($D7,الطلاب!$A$5:$A$44,0)),"") -> المقرأة الأولى | C7: =IFERROR(INDEX(الطلاب!$D$5:$D$44,MATCH($D7,الطلاب!$A$5:$A$44,0)),"") -> عبدالرحمن بن النعمان | D7: 3 | E7: =IFERROR(INDEX(الطلاب!$B$5:$B$44,MATCH($D7,الطلاب!$A$5:$A$44,0)),"") -> فهد المشيقح | F7: حاضر | G7: 95 | H7: 1 | I7: 22 | L7: =IF(AND($A7='أفضل 5 طلاب'!$C$3,$B7=الإعدادات!$C$8,$N7=1,ISNUMBER($G7)),$G7*100000+N($H7)*100+N($I7)+(1000-ROW())/10000,0) -> 0 | M7: =IF(AND($A7='أفضل 5 طلاب'!$C$3,$B7=الإعدادات!$C$9,$N7=1,ISNUMBER($G7)),$G7*100000+N($H7)*100+N($I7)+(1000-ROW())/10000,0) -> 0 | N7: =IF(OR($F7="حاضر",$F7="متأخر"),1,0) -> 1 | O7: =IF(OR($N7=1,$F7="معتذر",$F7="غائب"),IF(ISNUMBER($G7),$G7,IF($N7=1,"",0)),"") -> 95 | P7: =IF(ISNUMBER($O7),1,0) -> 1
A8: 1 | B8: =IFERROR(INDEX(الطلاب!$C$5:$C$44,MATCH($D8,الطلاب!$A$5:$A$44,0)),"") -> المقرأة الأولى | C8: =IFERROR(INDEX(الطلاب!$D$5:$D$44,MATCH($D8,الطلاب!$A$5:$A$44,0)),"") -> عبدالرحمن بن النعمان | D8: 4 | E8: =IFERROR(INDEX(الطلاب!$B$5:$B$44,MATCH($D8,الطلاب!$A$5:$A$44,0)),"") -> عبدالله الحفير | F8: حاضر | G8: 50 | H8: 0 | I8: 0 | L8: =IF(AND($A8='أفضل 5 طلاب'!$C$3,$B8=الإعدادات!$C$8,$N8=1,ISNUMBER($G8)),$G8*100000+N($H8)*100+N($I8)+(1000-ROW())/10000,0) -> 0 | M8: =IF(AND($A8='أفضل 5 طلاب'!$C$3,$B8=الإعدادات!$C$9,$N8=1,ISNUMBER($G8)),$G8*100000+N($H8)*100+N($I8)+(1000-ROW())/10000,0) -> 0 | N8: =IF(OR($F8="حاضر",$F8="متأخر"),1,0) -> 1 | O8: =IF(OR($N8=1,$F8="معتذر",$F8="غائب"),IF(ISNUMBER($G8),$G8,IF($N8=1,"",0)),"") -> 50 | P8: =IF(ISNUMBER($O8),1,0) -> 1
A9: 1 | B9: =IFERROR(INDEX(الطلاب!$C$5:$C$44,MATCH($D9,الطلاب!$A$5:$A$44,0)),"") -> المقرأة الأولى | C9: =IFERROR(INDEX(الطلاب!$D$5:$D$44,MATCH($D9,الطلاب!$A$5:$A$44,0)),"") -> عبدالرحمن بن النعمان | D9: 5 | E9: =IFERROR(INDEX(الطلاب!$B$5:$B$44,MATCH($D9,الطلاب!$A$5:$A$44,0)),"") -> زياد الدخيل الله | F9: حاضر | G9: 50 | H9: 0 | I9: 0 | L9: =IF(AND($A9='أفضل 5 طلاب'!$C$3,$B9=الإعدادات!$C$8,$N9=1,ISNUMBER($G9)),$G9*100000+N($H9)*100+N($I9)+(1000-ROW())/10000,0) -> 0 | M9: =IF(AND($A9='أفضل 5 طلاب'!$C$3,$B9=الإعدادات!$C$9,$N9=1,ISNUMBER($G9)),$G9*100000+N($H9)*100+N($I9)+(1000-ROW())/10000,0) -> 0 | N9: =IF(OR($F9="حاضر",$F9="متأخر"),1,0) -> 1 | O9: =IF(OR($N9=1,$F9="معتذر",$F9="غائب"),IF(ISNUMBER($G9),$G9,IF($N9=1,"",0)),"") -> 50 | P9: =IF(ISNUMBER($O9),1,0) -> 1
A10: 1 | B10: =IFERROR(INDEX(الطلاب!$C$5:$C$44,MATCH($D10,الطلاب!$A$5:$A$44,0)),"") -> المقرأة الأولى | C10: =IFERROR(INDEX(الطلاب!$D$5:$D$44,MATCH($D10,الطلاب!$A$5:$A$44,0)),"") -> ابن رجب | D10: 6 | E10: =IFERROR(INDEX(الطلاب!$B$5:$B$44,MATCH($D10,الطلاب!$A$5:$A$44,0)),"") -> عاصم الضبيعي | F10: حاضر | G10: 96 | H10: 0 | I10: 40 | L10: =IF(AND($A10='أفضل 5 طلاب'!$C$3,$B10=الإعدادات!$C$8,$N10=1,ISNUMBER($G10)),$G10*100000+N($H10)*100+N($I10)+(1000-ROW())/10000,0) -> 0 | M10: =IF(AND($A10='أفضل 5 طلاب'!$C$3,$B10=الإعدادات!$C$9,$N10=1,ISNUMBER($G10)),$G10*100000+N($H10)*100+N($I10)+(1000-ROW())/10000,0) -> 0 | N10: =IF(OR($F10="حاضر",$F10="متأخر"),1,0) -> 1 | O10: =IF(OR($N10=1,$F10="معتذر",$F10="غائب"),IF(ISNUMBER($G10),$G10,IF($N10=1,"",0)),"") -> 96 | P10: =IF(ISNUMBER($O10),1,0) -> 1
A11: 1 | B11: =IFERROR(INDEX(الطلاب!$C$5:$C$44,MATCH($D11,الطلاب!$A$5:$A$44,0)),"") -> المقرأة الأولى | C11: =IFERROR(INDEX(الطلاب!$D$5:$D$44,MATCH($D11,الطلاب!$A$5:$A$44,0)),"") -> ابن رجب | D11: 7 | E11: =IFERROR(INDEX(الطلاب!$B$5:$B$44,MATCH($D11,الطلاب!$A$5:$A$44,0)),"") -> محمد السعوي | F11: حاضر | G11: 97 | H11: 1 | I11: 40 | L11: =IF(AND($A11='أفضل 5 طلاب'!$C$3,$B11=الإعدادات!$C$8,$N11=1,ISNUMBER($G11)),$G11*100000+N($H11)*100+N($I11)+(1000-ROW())/10000,0) -> 0 | M11: =IF(AND($A11='أفضل 5 طلاب'!$C$3,$B11=الإعدادات!$C$9,$N11=1,ISNUMBER($G11)),$G11*100000+N($H11)*100+N($I11)+(1000-ROW())/10000,0) -> 0 | N11: =IF(OR($F11="حاضر",$F11="متأخر"),1,0) -> 1 | O11: =IF(OR($N11=1,$F11="معتذر",$F11="غائب"),IF(ISNUMBER($G11),$G11,IF($N11=1,"",0)),"") -> 97 | P11: =IF(ISNUMBER($O11),1,0) -> 1
A12: 1 | B12: =IFERROR(INDEX(الطلاب!$C$5:$C$44,MATCH($D12,الطلاب!$A$5:$A$44,0)),"") -> المقرأة الأولى | C12: =IFERROR(INDEX(الطلاب!$D$5:$D$44,MATCH($D12,الطلاب!$A$5:$A$44,0)),"") -> ابن رجب | D12: 8 | E12: =IFERROR(INDEX(الطلاب!$B$5:$B$44,MATCH($D12,الطلاب!$A$5:$A$44,0)),"") -> هشام المخلف | F12: حاضر | G12: 93 | H12: 1 | I12: 15 | L12: =IF(AND($A12='أفضل 5 طلاب'!$C$3,$B12=الإعدادات!$C$8,$N12=1,ISNUMBER($G12)),$G12*100000+N($H12)*100+N($I12)+(1000-ROW())/10000,0) -> 0 | M12: =IF(AND($A12='أفضل 5 طلاب'!$C$3,$B12=الإعدادات!$C$9,$N12=1,ISNUMBER($G12)),$G12*100000+N($H12)*100+N($I12)+(1000-ROW())/10000,0) -> 0 | N12: =IF(OR($F12="حاضر",$F12="متأخر"),1,0) -> 1 | O12: =IF(OR($N12=1,$F12="معتذر",$F12="غائب"),IF(ISNUMBER($G12),$G12,IF($N12=1,"",0)),"") -> 93 | P12: =IF(ISNUMBER($O12),1,0) -> 1
A13: 1 | B13: =IFERROR(INDEX(الطلاب!$C$5:$C$44,MATCH($D13,الطلاب!$A$5:$A$44,0)),"") -> المقرأة الأولى | C13: =IFERROR(INDEX(الطلاب!$D$5:$D$44,MATCH($D13,الطلاب!$A$5:$A$44,0)),"") -> ابن رجب | D13: 9 | E13: =IFERROR(INDEX(الطلاب!$B$5:$B$44,MATCH($D13,الطلاب!$A$5:$A$44,0)),"") -> اسامة السعدون | F13: معتذر | G13: 0 | H13: 0 | I13: 0 | L13: =IF(AND($A13='أفضل 5 طلاب'!$C$3,$B13=الإعدادات!$C$8,$N13=1,ISNUMBER($G13)),$G13*100000+N($H13)*100+N($I13)+(1000-ROW())/10000,0) -> 0 | M13: =IF(AND($A13='أفضل 5 طلاب'!$C$3,$B13=الإعدادات!$C$9,$N13=1,ISNUMBER($G13)),$G13*100000+N($H13)*100+N($I13)+(1000-ROW())/10000,0) -> 0 | N13: =IF(OR($F13="حاضر",$F13="متأخر"),1,0) -> 0 | O13: =IF(OR($N13=1,$F13="معتذر",$F13="غائب"),IF(ISNUMBER($G13),$G13,IF($N13=1,"",0)),"") -> 0 | P13: =IF(ISNUMBER($O13),1,0) -> 1
A14: 1 | B14: =IFERROR(INDEX(الطلاب!$C$5:$C$44,MATCH($D14,الطلاب!$A$5:$A$44,0)),"") -> المقرأة الأولى | C14: =IFERROR(INDEX(الطلاب!$D$5:$D$44,MATCH($D14,الطلاب!$A$5:$A$44,0)),"") -> حسان بن ثابت | D14: 10 | E14: =IFERROR(INDEX(الطلاب!$B$5:$B$44,MATCH($D14,الطلاب!$A$5:$A$44,0)),"") -> محمد الثنيان | F14: حاضر | G14: 94 | H14: 5 | I14: 30 | L14: =IF(AND($A14='أفضل 5 طلاب'!$C$3,$B14=الإعدادات!$C$8,$N14=1,ISNUMBER($G14)),$G14*100000+N($H14)*100+N($I14)+(1000-ROW())/10000,0) -> 0 | M14: =IF(AND($A14='أفضل 5 طلاب'!$C$3,$B14=الإعدادات!$C$9,$N14=1,ISNUMBER($G14)),$G14*100000+N($H14)*100+N($I14)+(1000-ROW())/10000,0) -> 0 | N14: =IF(OR($F14="حاضر",$F14="متأخر"),1,0) -> 1 | O14: =IF(OR($N14=1,$F14="معتذر",$F14="غائب"),IF(ISNUMBER($G14),$G14,IF($N14=1,"",0)),"") -> 94 | P14: =IF(ISNUMBER($O14),1,0) -> 1
A15: 1 | B15: =IFERROR(INDEX(الطلاب!$C$5:$C$44,MATCH($D15,الطلاب!$A$5:$A$44,0)),"") -> المقرأة الأولى | C15: =IFERROR(INDEX(الطلاب!$D$5:$D$44,MATCH($D15,الطلاب!$A$5:$A$44,0)),"") -> حسان بن ثابت | D15: 11 | E15: =IFERROR(INDEX(الطلاب!$B$5:$B$44,MATCH($D15,الطلاب!$A$5:$A$44,0)),"") -> كنان الجريفاني | F15: حاضر | G15: 85 | H15: 0 | I15: 40 | L15: =IF(AND($A15='أفضل 5 طلاب'!$C$3,$B15=الإعدادات!$C$8,$N15=1,ISNUMBER($G15)),$G15*100000+N($H15)*100+N($I15)+(1000-ROW())/10000,0) -> 0 | M15: =IF(AND($A15='أفضل 5 طلاب'!$C$3,$B15=الإعدادات!$C$9,$N15=1,ISNUMBER($G15)),$G15*100000+N($H15)*100+N($I15)+(1000-ROW())/10000,0) -> 0 | N15: =IF(OR($F15="حاضر",$F15="متأخر"),1,0) -> 1 | O15: =IF(OR($N15=1,$F15="معتذر",$F15="غائب"),IF(ISNUMBER($G15),$G15,IF($N15=1,"",0)),"") -> 85 | P15: =IF(ISNUMBER($O15),1,0) -> 1
A16: 1 | B16: =IFERROR(INDEX(الطلاب!$C$5:$C$44,MATCH($D16,الطلاب!$A$5:$A$44,0)),"") -> المقرأة الأولى | C16: =IFERROR(INDEX(الطلاب!$D$5:$D$44,MATCH($D16,الطلاب!$A$5:$A$44,0)),"") -> حسان بن ثابت | D16: 12 | E16: =IFERROR(INDEX(الطلاب!$B$5:$B$44,MATCH($D16,الطلاب!$A$5:$A$44,0)),"") -> عبدالمجيد الربعي | F16: حاضر | G16: 54 | H16: 0 | I16: 40 | L16: =IF(AND($A16='أفضل 5 طلاب'!$C$3,$B16=الإعدادات!$C$8,$N16=1,ISNUMBER($G16)),$G16*100000+N($H16)*100+N($I16)+(1000-ROW())/10000,0) -> 0 | M16: =IF(AND($A16='أفضل 5 طلاب'!$C$3,$B16=الإعدادات!$C$9,$N16=1,ISNUMBER($G16)),$G16*100000+N($H16)*100+N($I16)+(1000-ROW())/10000,0) -> 0 | N16: =IF(OR($F16="حاضر",$F16="متأخر"),1,0) -> 1 | O16: =IF(OR($N16=1,$F16="معتذر",$F16="غائب"),IF(ISNUMBER($G16),$G16,IF($N16=1,"",0)),"") -> 54 | P16: =IF(ISNUMBER($O16),1,0) -> 1
... A39: 1 | B39: =IFERROR(INDEX(الطلاب!$C$5:$C$44,MATCH($D39,الطلاب!$A$5:$A$44,0)),"") -> المقرأة الثانية | C39: =IFERROR(INDEX(الطلاب!$D$5:$D$44,MATCH($D39,الطلاب!$A$5:$A$44,0)),"") -> ابي بن مالك | D39: 35 | E39: =IFERROR(INDEX(الطلاب!$B$5:$B$44,MATCH($D39,الطلاب!$A$5:$A$44,0)),"") -> عبدالله الفايزي | F39: حاضر | G39: 60 | H39: 0 | I39: 20 | L39: =IF(AND($A39='أفضل 5 طلاب'!$C$3,$B39=الإعدادات!$C$8,$N39=1,ISNUMBER($G39)),$G39*100000+N($H39)*100+N($I39)+(1000-ROW())/10000,0) -> 0 | M39: =IF(AND($A39='أفضل 5 طلاب'!$C$3,$B39=الإعدادات!$C$9,$N39=1,ISNUMBER($G39)),$G39*100000+N($H39)*100+N($I39)+(1000-ROW())/10000,0) -> 0 | N39: =IF(OR($F39="حاضر",$F39="متأخر"),1,0) -> 1 | O39: =IF(OR($N39=1,$F39="معتذر",$F39="غائب"),IF(ISNUMBER($G39),$G39,IF($N39=1,"",0)),"") -> 60 | P39: =IF(ISNUMBER($O39),1,0) -> 1
A40: 1 | B40: =IFERROR(INDEX(الطلاب!$C$5:$C$44,MATCH($D40,الطلاب!$A$5:$A$44,0)),"") -> 0 | C40: =IFERROR(INDEX(الطلاب!$D$5:$D$44,MATCH($D40,الطلاب!$A$5:$A$44,0)),"") -> 0 | D40: 36 | E40: =IFERROR(INDEX(الطلاب!$B$5:$B$44,MATCH($D40,الطلاب!$A$5:$A$44,0)),"") -> عزام الحسن | L40: =IF(AND($A40='أفضل 5 طلاب'!$C$3,$B40=الإعدادات!$C$8,$N40=1,ISNUMBER($G40)),$G40*100000+N($H40)*100+N($I40)+(1000-ROW())/10000,0) -> 0 | M40: =IF(AND($A40='أفضل 5 طلاب'!$C$3,$B40=الإعدادات!$C$9,$N40=1,ISNUMBER($G40)),$G40*100000+N($H40)*100+N($I40)+(1000-ROW())/10000,0) -> 0 | N40: =IF(OR($F40="حاضر",$F40="متأخر"),1,0) -> 0 | O40: =IF(OR($N40=1,$F40="معتذر",$F40="غائب"),IF(ISNUMBER($G40),$G40,IF($N40=1,"",0)),"") | P40: =IF(ISNUMBER($O40),1,0) -> 0
A41: 1 | B41: =IFERROR(INDEX(الطلاب!$C$5:$C$44,MATCH($D41,الطلاب!$A$5:$A$44,0)),"") -> المقرأة الأولى | C41: =IFERROR(INDEX(الطلاب!$D$5:$D$44,MATCH($D41,الطلاب!$A$5:$A$44,0)),"") -> عبدالرحمن بن النعمان | D41: 37 | E41: =IFERROR(INDEX(الطلاب!$B$5:$B$44,MATCH($D41,الطلاب!$A$5:$A$44,0)),"") -> أسامة السعوي | L41: =IF(AND($A41='أفضل 5 طلاب'!$C$3,$B41=الإعدادات!$C$8,$N41=1,ISNUMBER($G41)),$G41*100000+N($H41)*100+N($I41)+(1000-ROW())/10000,0) -> 0 | M41: =IF(AND($A41='أفضل 5 طلاب'!$C$3,$B41=الإعدادات!$C$9,$N41=1,ISNUMBER($G41)),$G41*100000+N($H41)*100+N($I41)+(1000-ROW())/10000,0) -> 0 | N41: =IF(OR($F41="حاضر",$F41="متأخر"),1,0) -> 0 | O41: =IF(OR($N41=1,$F41="معتذر",$F41="غائب"),IF(ISNUMBER($G41),$G41,IF($N41=1,"",0)),"") | P41: =IF(ISNUMBER($O41),1,0) -> 0
A42: 1 | B42: =IFERROR(INDEX(الطلاب!$C$5:$C$44,MATCH($D42,الطلاب!$A$5:$A$44,0)),"") -> المقرأة الأولى | C42: =IFERROR(INDEX(الطلاب!$D$5:$D$44,MATCH($D42,الطلاب!$A$5:$A$44,0)),"") -> حسان بن ثابت | D42: 38 | E42: =IFERROR(INDEX(الطلاب!$B$5:$B$44,MATCH($D42,الطلاب!$A$5:$A$44,0)),"") -> عاصم الضالع | L42: =IF(AND($A42='أفضل 5 طلاب'!$C$3,$B42=الإعدادات!$C$8,$N42=1,ISNUMBER($G42)),$G42*100000+N($H42)*100+N($I42)+(1000-ROW())/10000,0) -> 0 | M42: =IF(AND($A42='أفضل 5 طلاب'!$C$3,$B42=الإعدادات!$C$9,$N42=1,ISNUMBER($G42)),$G42*100000+N($H42)*100+N($I42)+(1000-ROW())/10000,0) -> 0 | N42: =IF(OR($F42="حاضر",$F42="متأخر"),1,0) -> 0 | O42: =IF(OR($N42=1,$F42="معتذر",$F42="غائب"),IF(ISNUMBER($G42),$G42,IF($N42=1,"",0)),"") | P42: =IF(ISNUMBER($O42),1,0) -> 0
A43: 1 | B43: =IFERROR(INDEX(الطلاب!$C$5:$C$44,MATCH($D43,الطلاب!$A$5:$A$44,0)),"") -> 0 | C43: =IFERROR(INDEX(الطلاب!$D$5:$D$44,MATCH($D43,الطلاب!$A$5:$A$44,0)),"") -> 0 | D43: 39 | E43: =IFERROR(INDEX(الطلاب!$B$5:$B$44,MATCH($D43,الطلاب!$A$5:$A$44,0)),"") -> 0 | L43: =IF(AND($A43='أفضل 5 طلاب'!$C$3,$B43=الإعدادات!$C$8,$N43=1,ISNUMBER($G43)),$G43*100000+N($H43)*100+N($I43)+(1000-ROW())/10000,0) -> 0 | M43: =IF(AND($A43='أفضل 5 طلاب'!$C$3,$B43=الإعدادات!$C$9,$N43=1,ISNUMBER($G43)),$G43*100000+N($H43)*100+N($I43)+(1000-ROW())/10000,0) -> 0 | N43: =IF(OR($F43="حاضر",$F43="متأخر"),1,0) -> 0 | O43: =IF(OR($N43=1,$F43="معتذر",$F43="غائب"),IF(ISNUMBER($G43),$G43,IF($N43=1,"",0)),"") | P43: =IF(ISNUMBER($O43),1,0) -> 0
A44: 1 | B44: =IFERROR(INDEX(الطلاب!$C$5:$C$44,MATCH($D44,الطلاب!$A$5:$A$44,0)),"") -> 0 | C44: =IFERROR(INDEX(الطلاب!$D$5:$D$44,MATCH($D44,الطلاب!$A$5:$A$44,0)),"") -> 0 | D44: 40 | E44: =IFERROR(INDEX(الطلاب!$B$5:$B$44,MATCH($D44,الطلاب!$A$5:$A$44,0)),"") -> 0 | L44: =IF(AND($A44='أفضل 5 طلاب'!$C$3,$B44=الإعدادات!$C$8,$N44=1,ISNUMBER($G44)),$G44*100000+N($H44)*100+N($I44)+(1000-ROW())/10000,0) -> 0 | M44: =IF(AND($A44='أفضل 5 طلاب'!$C$3,$B44=الإعدادات!$C$9,$N44=1,ISNUMBER($G44)),$G44*100000+N($H44)*100+N($I44)+(1000-ROW())/10000,0) -> 0 | N44: =IF(OR($F44="حاضر",$F44="متأخر"),1,0) -> 0 | O44: =IF(OR($N44=1,$F44="معتذر",$F44="غائب"),IF(ISNUMBER($G44),$G44,IF($N44=1,"",0)),"") | P44: =IF(ISNUMBER($O44),1,0) -> 0
A45: 2 | B45: =IFERROR(INDEX(الطلاب!$C$5:$C$44,MATCH($D45,الطلاب!$A$5:$A$44,0)),"") -> المقرأة الأولى | C45: =IFERROR(INDEX(الطلاب!$D$5:$D$44,MATCH($D45,الطلاب!$A$5:$A$44,0)),"") -> عبدالرحمن بن النعمان | D45: 1 | E45: =IFERROR(INDEX(الطلاب!$B$5:$B$44,MATCH($D45,الطلاب!$A$5:$A$44,0)),"") -> غسان اليحيى | F45: حاضر | G45: 93 | H45: 6 | I45: 40 | L45: =IF(AND($A45='أفضل 5 طلاب'!$C$3,$B45=الإعدادات!$C$8,$N45=1,ISNUMBER($G45)),$G45*100000+N($H45)*100+N($I45)+(1000-ROW())/10000,0) -> 9300640.1 | M45: =IF(AND($A45='أفضل 5 طلاب'!$C$3,$B45=الإعدادات!$C$9,$N45=1,ISNUMBER($G45)),$G45*100000+N($H45)*100+N($I45)+(1000-ROW())/10000,0) -> 0 | N45: =IF(OR($F45="حاضر",$F45="متأخر"),1,0) -> 1 | O45: =IF(OR($N45=1,$F45="معتذر",$F45="غائب"),IF(ISNUMBER($G45),$G45,IF($N45=1,"",0)),"") -> 93 | P45: =IF(ISNUMBER($O45),1,0) -> 1
A46: 2 | B46: =IFERROR(INDEX(الطلاب!$C$5:$C$44,MATCH($D46,الطلاب!$A$5:$A$44,0)),"") -> المقرأة الأولى | C46: =IFERROR(INDEX(الطلاب!$D$5:$D$44,MATCH($D46,الطلاب!$A$5:$A$44,0)),"") -> عبدالرحمن بن النعمان | D46: 2 | E46: =IFERROR(INDEX(الطلاب!$B$5:$B$44,MATCH($D46,الطلاب!$A$5:$A$44,0)),"") -> صالح الشريف | F46: حاضر | G46: 87 | H46: 1 | I46: 30 | L46: =IF(AND($A46='أفضل 5 طلاب'!$C$3,$B46=الإعدادات!$C$8,$N46=1,ISNUMBER($G46)),$G46*100000+N($H46)*100+N($I46)+(1000-ROW())/10000,0) -> 8700130.1 | M46: =IF(AND($A46='أفضل 5 طلاب'!$C$3,$B46=الإعدادات!$C$9,$N46=1,ISNUMBER($G46)),$G46*100000+N($H46)*100+N($I46)+(1000-ROW())/10000,0) -> 0 | N46: =IF(OR($F46="حاضر",$F46="متأخر"),1,0) -> 1 | O46: =IF(OR($N46=1,$F46="معتذر",$F46="غائب"),IF(ISNUMBER($G46),$G46,IF($N46=1,"",0)),"") -> 87 | P46: =IF(ISNUMBER($O46),1,0) -> 1
A47: 2 | B47: =IFERROR(INDEX(الطلاب!$C$5:$C$44,MATCH($D47,الطلاب!$A$5:$A$44,0)),"") -> المقرأة الأولى | C47: =IFERROR(INDEX(الطلاب!$D$5:$D$44,MATCH($D47,الطلاب!$A$5:$A$44,0)),"") -> عبدالرحمن بن النعمان | D47: 3 | E47: =IFERROR(INDEX(الطلاب!$B$5:$B$44,MATCH($D47,الطلاب!$A$5:$A$44,0)),"") -> فهد المشيقح | F47: حاضر | G47: 99 | H47: 4 | I47: 30 | L47: =IF(AND($A47='أفضل 5 طلاب'!$C$3,$B47=الإعدادات!$C$8,$N47=1,ISNUMBER($G47)),$G47*100000+N($H47)*100+N($I47)+(1000-ROW())/10000,0) -> 9900430.1 | M47: =IF(AND($A47='أفضل 5 طلاب'!$C$3,$B47=الإعدادات!$C$9,$N47=1,ISNUMBER($G47)),$G47*100000+N($H47)*100+N($I47)+(1000-ROW())/10000,0) -> 0 | N47: =IF(OR($F47="حاضر",$F47="متأخر"),1,0) -> 1 | O47: =IF(OR($N47=1,$F47="معتذر",$F47="غائب"),IF(ISNUMBER($G47),$G47,IF($N47=1,"",0)),"") -> 99 | P47: =IF(ISNUMBER($O47),1,0) -> 1
A48: 2 | B48: =IFERROR(INDEX(الطلاب!$C$5:$C$44,MATCH($D48,الطلاب!$A$5:$A$44,0)),"") -> المقرأة الأولى | C48: =IFERROR(INDEX(الطلاب!$D$5:$D$44,MATCH($D48,الطلاب!$A$5:$A$44,0)),"") -> عبدالرحمن بن النعمان | D48: 4 | E48: =IFERROR(INDEX(الطلاب!$B$5:$B$44,MATCH($D48,الطلاب!$A$5:$A$44,0)),"") -> عبدالله الحفير | F48: حاضر | G48: 100 | H48: 4 | I48: 28 | L48: =IF(AND($A48='أفضل 5 طلاب'!$C$3,$B48=الإعدادات!$C$8,$N48=1,ISNUMBER($G48)),$G48*100000+N($H48)*100+N($I48)+(1000-ROW())/10000,0) -> 10000428 | M48: =IF(AND($A48='أفضل 5 طلاب'!$C$3,$B48=الإعدادات!$C$9,$N48=1,ISNUMBER($G48)),$G48*100000+N($H48)*100+N($I48)+(1000-ROW())/10000,0) -> 0 | N48: =IF(OR($F48="حاضر",$F48="متأخر"),1,0) -> 1 | O48: =IF(OR($N48=1,$F48="معتذر",$F48="غائب"),IF(ISNUMBER($G48),$G48,IF($N48=1,"",0)),"") -> 100 | P48: =IF(ISNUMBER($O48),1,0) -> 1
A49: 2 | B49: =IFERROR(INDEX(الطلاب!$C$5:$C$44,MATCH($D49,الطلاب!$A$5:$A$44,0)),"") -> المقرأة الأولى | C49: =IFERROR(INDEX(الطلاب!$D$5:$D$44,MATCH($D49,الطلاب!$A$5:$A$44,0)),"") -> عبدالرحمن بن النعمان | D49: 5 | E49: =IFERROR(INDEX(الطلاب!$B$5:$B$44,MATCH($D49,الطلاب!$A$5:$A$44,0)),"") -> زياد الدخيل الله | F49: حاضر | G49: 87 | H49: 3 | I49: 40 | L49: =IF(AND($A49='أفضل 5 طلاب'!$C$3,$B49=الإعدادات!$C$8,$N49=1,ISNUMBER($G49)),$G49*100000+N($H49)*100+N($I49)+(1000-ROW())/10000,0) -> 8700340.1 | M49: =IF(AND($A49='أفضل 5 طلاب'!$C$3,$B49=الإعدادات!$C$9,$N49=1,ISNUMBER($G49)),$G49*100000+N($H49)*100+N($I49)+(1000-ROW())/10000,0) -> 0 | N49: =IF(OR($F49="حاضر",$F49="متأخر"),1,0) -> 1 | O49: =IF(OR($N49=1,$F49="معتذر",$F49="غائب"),IF(ISNUMBER($G49),$G49,IF($N49=1,"",0)),"") -> 87 | P49: =IF(ISNUMBER($O49),1,0) -> 1
A50: 2 | B50: =IFERROR(INDEX(الطلاب!$C$5:$C$44,MATCH($D50,الطلاب!$A$5:$A$44,0)),"") -> المقرأة الأولى | C50: =IFERROR(INDEX(الطلاب!$D$5:$D$44,MATCH($D50,الطلاب!$A$5:$A$44,0)),"") -> ابن رجب | D50: 6 | E50: =IFERROR(INDEX(الطلاب!$B$5:$B$44,MATCH($D50,الطلاب!$A$5:$A$44,0)),"") -> عاصم الضبيعي | F50: حاضر | G50: 91 | H50: 3 | I50: 20 | L50: =IF(AND($A50='أفضل 5 طلاب'!$C$3,$B50=الإعدادات!$C$8,$N50=1,ISNUMBER($G50)),$G50*100000+N($H50)*100+N($I50)+(1000-ROW())/10000,0) -> 9100320.1 | M50: =IF(AND($A50='أفضل 5 طلاب'!$C$3,$B50=الإعدادات!$C$9,$N50=1,ISNUMBER($G50)),$G50*100000+N($H50)*100+N($I50)+(1000-ROW())/10000,0) -> 0 | N50: =IF(OR($F50="حاضر",$F50="متأخر"),1,0) -> 1 | O50: =IF(OR($N50=1,$F50="معتذر",$F50="غائب"),IF(ISNUMBER($G50),$G50,IF($N50=1,"",0)),"") -> 91 | P50: =IF(ISNUMBER($O50),1,0) -> 1
A51: 2 | B51: =IFERROR(INDEX(الطلاب!$C$5:$C$44,MATCH($D51,الطلاب!$A$5:$A$44,0)),"") -> المقرأة الأولى | C51: =IFERROR(INDEX(الطلاب!$D$5:$D$44,MATCH($D51,الطلاب!$A$5:$A$44,0)),"") -> ابن رجب | D51: 7 | E51: =IFERROR(INDEX(الطلاب!$B$5:$B$44,MATCH($D51,الطلاب!$A$5:$A$44,0)),"") -> محمد السعوي | F51: حاضر | G51: 71 | H51: 0 | I51: 40 | L51: =IF(AND($A51='أفضل 5 طلاب'!$C$3,$B51=الإعدادات!$C$8,$N51=1,ISNUMBER($G51)),$G51*100000+N($H51)*100+N($I51)+(1000-ROW())/10000,0) -> 7100040.1 | M51: =IF(AND($A51='أفضل 5 طلاب'!$C$3,$B51=الإعدادات!$C$9,$N51=1,ISNUMBER($G51)),$G51*100000+N($H51)*100+N($I51)+(1000-ROW())/10000,0) -> 0 | N51: =IF(OR($F51="حاضر",$F51="متأخر"),1,0) -> 1 | O51: =IF(OR($N51=1,$F51="معتذر",$F51="غائب"),IF(ISNUMBER($G51),$G51,IF($N51=1,"",0)),"") -> 71 | P51: =IF(ISNUMBER($O51),1,0) -> 1
A52: 2 | B52: =IFERROR(INDEX(الطلاب!$C$5:$C$44,MATCH($D52,الطلاب!$A$5:$A$44,0)),"") -> المقرأة الأولى | C52: =IFERROR(INDEX(الطلاب!$D$5:$D$44,MATCH($D52,الطلاب!$A$5:$A$44,0)),"") -> ابن رجب | D52: 8 | E52: =IFERROR(INDEX(الطلاب!$B$5:$B$44,MATCH($D52,الطلاب!$A$5:$A$44,0)),"") -> هشام المخلف | F52: حاضر | G52: 93 | H52: 2 | I52: 20 | L52: =IF(AND($A52='أفضل 5 طلاب'!$C$3,$B52=الإعدادات!$C$8,$N52=1,ISNUMBER($G52)),$G52*100000+N($H52)*100+N($I52)+(1000-ROW())/10000,0) -> 9300220.1 | M52: =IF(AND($A52='أفضل 5 طلاب'!$C$3,$B52=الإعدادات!$C$9,$N52=1,ISNUMBER($G52)),$G52*100000+N($H52)*100+N($I52)+(1000-ROW())/10000,0) -> 0 | N52: =IF(OR($F52="حاضر",$F52="متأخر"),1,0) -> 1 | O52: =IF(OR($N52=1,$F52="معتذر",$F52="غائب"),IF(ISNUMBER($G52),$G52,IF($N52=1,"",0)),"") -> 93 | P52: =IF(ISNUMBER($O52),1,0) -> 1
A53: 2 | B53: =IFERROR(INDEX(الطلاب!$C$5:$C$44,MATCH($D53,الطلاب!$A$5:$A$44,0)),"") -> المقرأة الأولى | C53: =IFERROR(INDEX(الطلاب!$D$5:$D$44,MATCH($D53,الطلاب!$A$5:$A$44,0)),"") -> ابن رجب | D53: 9 | E53: =IFERROR(INDEX(الطلاب!$B$5:$B$44,MATCH($D53,الطلاب!$A$5:$A$44,0)),"") -> اسامة السعدون | F53: معتذر | G53: 15 | L53: =IF(AND($A53='أفضل 5 طلاب'!$C$3,$B53=الإعدادات!$C$8,$N53=1,ISNUMBER($G53)),$G53*100000+N($H53)*100+N($I53)+(1000-ROW())/10000,0) -> 0 | M53: =IF(AND($A53='أفضل 5 طلاب'!$C$3,$B53=الإعدادات!$C$9,$N53=1,ISNUMBER($G53)),$G53*100000+N($H53)*100+N($I53)+(1000-ROW())/10000,0) -> 0 | N53: =IF(OR($F53="حاضر",$F53="متأخر"),1,0) -> 0 | O53: =IF(OR($N53=1,$F53="معتذر",$F53="غائب"),IF(ISNUMBER($G53),$G53,IF($N53=1,"",0)),"") -> 15 | P53: =IF(ISNUMBER($O53),1,0) -> 1
A54: 2 | B54: =IFERROR(INDEX(الطلاب!$C$5:$C$44,MATCH($D54,الطلاب!$A$5:$A$44,0)),"") -> المقرأة الأولى | C54: =IFERROR(INDEX(الطلاب!$D$5:$D$44,MATCH($D54,الطلاب!$A$5:$A$44,0)),"") -> حسان بن ثابت | D54: 10 | E54: =IFERROR(INDEX(الطلاب!$B$5:$B$44,MATCH($D54,الطلاب!$A$5:$A$44,0)),"") -> محمد الثنيان | F54: حاضر | G54: 99 | H54: 3 | I54: 8 | L54: =IF(AND($A54='أفضل 5 طلاب'!$C$3,$B54=الإعدادات!$C$8,$N54=1,ISNUMBER($G54)),$G54*100000+N($H54)*100+N($I54)+(1000-ROW())/10000,0) -> 9900308.1 | M54: =IF(AND($A54='أفضل 5 طلاب'!$C$3,$B54=الإعدادات!$C$9,$N54=1,ISNUMBER($G54)),$G54*100000+N($H54)*100+N($I54)+(1000-ROW())/10000,0) -> 0 | N54: =IF(OR($F54="حاضر",$F54="متأخر"),1,0) -> 1 | O54: =IF(OR($N54=1,$F54="معتذر",$F54="غائب"),IF(ISNUMBER($G54),$G54,IF($N54=1,"",0)),"") -> 99 | P54: =IF(ISNUMBER($O54),1,0) -> 1
A55: 2 | B55: =IFERROR(INDEX(الطلاب!$C$5:$C$44,MATCH($D55,الطلاب!$A$5:$A$44,0)),"") -> المقرأة الأولى | C55: =IFERROR(INDEX(الطلاب!$D$5:$D$44,MATCH($D55,الطلاب!$A$5:$A$44,0)),"") -> حسان بن ثابت | D55: 11 | E55: =IFERROR(INDEX(الطلاب!$B$5:$B$44,MATCH($D55,الطلاب!$A$5:$A$44,0)),"") -> كنان الجريفاني | F55: حاضر | G55: 99 | H55: 3 | I55: 17 | L55: =IF(AND($A55='أفضل 5 طلاب'!$C$3,$B55=الإعدادات!$C$8,$N55=1,ISNUMBER($G55)),$G55*100000+N($H55)*100+N($I55)+(1000-ROW())/10000,0) -> 9900317.1 | M55: =IF(AND($A55='أفضل 5 طلاب'!$C$3,$B55=الإعدادات!$C$9,$N55=1,ISNUMBER($G55)),$G55*100000+N($H55)*100+N($I55)+(1000-ROW())/10000,0) -> 0 | N55: =IF(OR($F55="حاضر",$F55="متأخر"),1,0) -> 1 | O55: =IF(OR($N55=1,$F55="معتذر",$F55="غائب"),IF(ISNUMBER($G55),$G55,IF($N55=1,"",0)),"") -> 99 | P55: =IF(ISNUMBER($O55),1,0) -> 1
A56: 2 | B56: =IFERROR(INDEX(الطلاب!$C$5:$C$44,MATCH($D56,الطلاب!$A$5:$A$44,0)),"") -> المقرأة الأولى | C56: =IFERROR(INDEX(الطلاب!$D$5:$D$44,MATCH($D56,الطلاب!$A$5:$A$44,0)),"") -> حسان بن ثابت | D56: 12 | E56: =IFERROR(INDEX(الطلاب!$B$5:$B$44,MATCH($D56,الطلاب!$A$5:$A$44,0)),"") -> عبدالمجيد الربعي | F56: حاضر | G56: 70 | H56: 5 | I56: 40 | L56: =IF(AND($A56='أفضل 5 طلاب'!$C$3,$B56=الإعدادات!$C$8,$N56=1,ISNUMBER($G56)),$G56*100000+N($H56)*100+N($I56)+(1000-ROW())/10000,0) -> 7000540.1 | M56: =IF(AND($A56='أفضل 5 طلاب'!$C$3,$B56=الإعدادات!$C$9,$N56=1,ISNUMBER($G56)),$G56*100000+N($H56)*100+N($I56)+(1000-ROW())/10000,0) -> 0 | N56: =IF(OR($F56="حاضر",$F56="متأخر"),1,0) -> 1 | O56: =IF(OR($N56=1,$F56="معتذر",$F56="غائب"),IF(ISNUMBER($G56),$G56,IF($N56=1,"",0)),"") -> 70 | P56: =IF(ISNUMBER($O56),1,0) -> 1
A57: 2 | B57: =IFERROR(INDEX(الطلاب!$C$5:$C$44,MATCH($D57,الطلاب!$A$5:$A$44,0)),"") -> المقرأة الأولى | C57: =IFERROR(INDEX(الطلاب!$D$5:$D$44,MATCH($D57,الطلاب!$A$5:$A$44,0)),"") -> حسان بن ثابت | D57: 13 | E57: =IFERROR(INDEX(الطلاب!$B$5:$B$44,MATCH($D57,الطلاب!$A$5:$A$44,0)),"") -> عبدالله التويجري | F57: معتذر | G57: 15 | L57: =IF(AND($A57='أفضل 5 طلاب'!$C$3,$B57=الإعدادات!$C$8,$N57=1,ISNUMBER($G57)),$G57*100000+N($H57)*100+N($I57)+(1000-ROW())/10000,0) -> 0 | M57: =IF(AND($A57='أفضل 5 طلاب'!$C$3,$B57=الإعدادات!$C$9,$N57=1,ISNUMBER($G57)),$G57*100000+N($H57)*100+N($I57)+(1000-ROW())/10000,0) -> 0 | N57: =IF(OR($F57="حاضر",$F57="متأخر"),1,0) -> 0 | O57: =IF(OR($N57=1,$F57="معتذر",$F57="غائب"),IF(ISNUMBER($G57),$G57,IF($N57=1,"",0)),"") -> 15 | P57: =IF(ISNUMBER($O57),1,0) -> 1
A58: 2 | B58: =IFERROR(INDEX(الطلاب!$C$5:$C$44,MATCH($D58,الطلاب!$A$5:$A$44,0)),"") -> المقرأة الأولى | C58: =IFERROR(INDEX(الطلاب!$D$5:$D$44,MATCH($D58,الطلاب!$A$5:$A$44,0)),"") -> حسان بن ثابت | D58: 14 | E58: =IFERROR(INDEX(الطلاب!$B$5:$B$44,MATCH($D58,الطلاب!$A$5:$A$44,0)),"") -> حسام التويجري | F58: معتذر | G58: 48 | H58: 0 | I58: 40 | L58: =IF(AND($A58='أفضل 5 طلاب'!$C$3,$B58=الإعدادات!$C$8,$N58=1,ISNUMBER($G58)),$G58*100000+N($H58)*100+N($I58)+(1000-ROW())/10000,0) -> 0 | M58: =IF(AND($A58='أفضل 5 طلاب'!$C$3,$B58=الإعدادات!$C$9,$N58=1,ISNUMBER($G58)),$G58*100000+N($H58)*100+N($I58)+(1000-ROW())/10000,0) -> 0 | N58: =IF(OR($F58="حاضر",$F58="متأخر"),1,0) -> 0 | O58: =IF(OR($N58=1,$F58="معتذر",$F58="غائب"),IF(ISNUMBER($G58),$G58,IF($N58=1,"",0)),"") -> 48 | P58: =IF(ISNUMBER($O58),1,0) -> 1
A59: 2 | B59: =IFERROR(INDEX(الطلاب!$C$5:$C$44,MATCH($D59,الطلاب!$A$5:$A$44,0)),"") -> المقرأة الأولى | C59: =IFERROR(INDEX(الطلاب!$D$5:$D$44,MATCH($D59,الطلاب!$A$5:$A$44,0)),"") -> حسان بن ثابت | D59: 15 | E59: =IFERROR(INDEX(الطلاب!$B$5:$B$44,MATCH($D59,الطلاب!$A$5:$A$44,0)),"") -> عبدالرحمن البريدي | F59: معتذر | G59: 62 | H59: 4 | I59: 20 | L59: =IF(AND($A59='أفضل 5 طلاب'!$C$3,$B59=الإعدادات!$C$8,$N59=1,ISNUMBER($G59)),$G59*100000+N($H59)*100+N($I59)+(1000-ROW())/10000,0) -> 0 | M59: =IF(AND($A59='أفضل 5 طلاب'!$C$3,$B59=الإعدادات!$C$9,$N59=1,ISNUMBER($G59)),$G59*100000+N($H59)*100+N($I59)+(1000-ROW())/10000,0) -> 0 | N59: =IF(OR($F59="حاضر",$F59="متأخر"),1,0) -> 0 | O59: =IF(OR($N59=1,$F59="معتذر",$F59="غائب"),IF(ISNUMBER($G59),$G59,IF($N59=1,"",0)),"") -> 62 | P59: =IF(ISNUMBER($O59),1,0) -> 1
A60: 2 | B60: =IFERROR(INDEX(الطلاب!$C$5:$C$44,MATCH($D60,الطلاب!$A$5:$A$44,0)),"") -> المقرأة الأولى | C60: =IFERROR(INDEX(الطلاب!$D$5:$D$44,MATCH($D60,الطلاب!$A$5:$A$44,0)),"") -> حسان بن ثابت | D60: 16 | E60: =IFERROR(INDEX(الطلاب!$B$5:$B$44,MATCH($D60,الطلاب!$A$5:$A$44,0)),"") -> عبدالرحمن بازرعة | F60: حاضر | G60: 87 | H60: 7 | I60: 15 | L60: =IF(AND($A60='أفضل 5 طلاب'!$C$3,$B60=الإعدادات!$C$8,$N60=1,ISNUMBER($G60)),$G60*100000+N($H60)*100+N($I60)+(1000-ROW())/10000,0) -> 8700715.1 | M60: =IF(AND($A60='أفضل 5 طلاب'!$C$3,$B60=الإعدادات!$C$9,$N60=1,ISNUMBER($G60)),$G60*100000+N($H60)*100+N($I60)+(1000-ROW())/10000,0) -> 0 | N60: =IF(OR($F60="حاضر",$F60="متأخر"),1,0) -> 1 | O60: =IF(OR($N60=1,$F60="معتذر",$F60="غائب"),IF(ISNUMBER($G60),$G60,IF($N60=1,"",0)),"") -> 87 | P60: =IF(ISNUMBER($O60),1,0) -> 1
A61: 2 | B61: =IFERROR(INDEX(الطلاب!$C$5:$C$44,MATCH($D61,الطلاب!$A$5:$A$44,0)),"") -> المقرأة الأولى | C61: =IFERROR(INDEX(الطلاب!$D$5:$D$44,MATCH($D61,الطلاب!$A$5:$A$44,0)),"") -> حسان بن ثابت | D61: 17 | E61: =IFERROR(INDEX(الطلاب!$B$5:$B$44,MATCH($D61,الطلاب!$A$5:$A$44,0)),"") -> عبدالله الضحيان | F61: حاضر | G61: 84 | H61: 3 | I61: 40 | L61: =IF(AND($A61='أفضل 5 طلاب'!$C$3,$B61=الإعدادات!$C$8,$N61=1,ISNUMBER($G61)),$G61*100000+N($H61)*100+N($I61)+(1000-ROW())/10000,0) -> 8400340.1 | M61: =IF(AND($A61='أفضل 5 طلاب'!$C$3,$B61=الإعدادات!$C$9,$N61=1,ISNUMBER($G61)),$G61*100000+N($H61)*100+N($I61)+(1000-ROW())/10000,0) -> 0 | N61: =IF(OR($F61="حاضر",$F61="متأخر"),1,0) -> 1 | O61: =IF(OR($N61=1,$F61="معتذر",$F61="غائب"),IF(ISNUMBER($G61),$G61,IF($N61=1,"",0)),"") -> 84 | P61: =IF(ISNUMBER($O61),1,0) -> 1
A62: 2 | B62: =IFERROR(INDEX(الطلاب!$C$5:$C$44,MATCH($D62,الطلاب!$A$5:$A$44,0)),"") -> المقرأة الأولى | C62: =IFERROR(INDEX(الطلاب!$D$5:$D$44,MATCH($D62,الطلاب!$A$5:$A$44,0)),"") -> حسان بن ثابت | D62: 18 | E62: =IFERROR(INDEX(الطلاب!$B$5:$B$44,MATCH($D62,الطلاب!$A$5:$A$44,0)),"") -> فيصل الدخيل | F62: حاضر | G62: 94 | H62: 4 | I62: 10 | L62: =IF(AND($A62='أفضل 5 طلاب'!$C$3,$B62=الإعدادات!$C$8,$N62=1,ISNUMBER($G62)),$G62*100000+N($H62)*100+N($I62)+(1000-ROW())/10000,0) -> 9400410.1 | M62: =IF(AND($A62='أفضل 5 طلاب'!$C$3,$B62=الإعدادات!$C$9,$N62=1,ISNUMBER($G62)),$G62*100000+N($H62)*100+N($I62)+(1000-ROW())/10000,0) -> 0 | N62: =IF(OR($F62="حاضر",$F62="متأخر"),1,0) -> 1 | O62: =IF(OR($N62=1,$F62="معتذر",$F62="غائب"),IF(ISNUMBER($G62),$G62,IF($N62=1,"",0)),"") -> 94 | P62: =IF(ISNUMBER($O62),1,0) -> 1
A63: 2 | B63: =IFERROR(INDEX(الطلاب!$C$5:$C$44,MATCH($D63,الطلاب!$A$5:$A$44,0)),"") -> المقرأة الأولى | C63: =IFERROR(INDEX(الطلاب!$D$5:$D$44,MATCH($D63,الطلاب!$A$5:$A$44,0)),"") -> حسان بن ثابت | D63: 19 | E63: =IFERROR(INDEX(الطلاب!$B$5:$B$44,MATCH($D63,الطلاب!$A$5:$A$44,0)),"") -> سليمان المحيميد | F63: معتذر | G63: 62 | H63: 0 | I63: 20 | L63: =IF(AND($A63='أفضل 5 طلاب'!$C$3,$B63=الإعدادات!$C$8,$N63=1,ISNUMBER($G63)),$G63*100000+N($H63)*100+N($I63)+(1000-ROW())/10000,0) -> 0 | M63: =IF(AND($A63='أفضل 5 طلاب'!$C$3,$B63=الإعدادات!$C$9,$N63=1,ISNUMBER($G63)),$G63*100000+N($H63)*100+N($I63)+(1000-ROW())/10000,0) -> 0 | N63: =IF(OR($F63="حاضر",$F63="متأخر"),1,0) -> 0 | O63: =IF(OR($N63=1,$F63="معتذر",$F63="غائب"),IF(ISNUMBER($G63),$G63,IF($N63=1,"",0)),"") -> 62 | P63: =IF(ISNUMBER($O63),1,0) -> 1
A64: 2 | B64: =IFERROR(INDEX(الطلاب!$C$5:$C$44,MATCH($D64,الطلاب!$A$5:$A$44,0)),"") -> المقرأة الثانية | C64: =IFERROR(INDEX(الطلاب!$D$5:$D$44,MATCH($D64,الطلاب!$A$5:$A$44,0)),"") -> ابن رجب | D64: 20 | E64: =IFERROR(INDEX(الطلاب!$B$5:$B$44,MATCH($D64,الطلاب!$A$5:$A$44,0)),"") -> اصيل التويجري | F64: غائب | L64: =IF(AND($A64='أفضل 5 طلاب'!$C$3,$B64=الإعدادات!$C$8,$N64=1,ISNUMBER($G64)),$G64*100000+N($H64)*100+N($I64)+(1000-ROW())/10000,0) -> 0 | M64: =IF(AND($A64='أفضل 5 طلاب'!$C$3,$B64=الإعدادات!$C$9,$N64=1,ISNUMBER($G64)),$G64*100000+N($H64)*100+N($I64)+(1000-ROW())/10000,0) -> 0 | N64: =IF(OR($F64="حاضر",$F64="متأخر"),1,0) -> 0 | O64: =IF(OR($N64=1,$F64="معتذر",$F64="غائب"),IF(ISNUMBER($G64),$G64,IF($N64=1,"",0)),"") -> 0 | P64: =IF(ISNUMBER($O64),1,0) -> 1
...

Sheet تقرير المقرأة 1
A1: ="تقرير "&الإعدادات!$C$8&" — نسبة إنجاز الطلاب أسبوعيًا" -> تقرير المقرأة الأولى — نسبة إنجاز الطلاب أسبوعيًا
B3: المقرأة: | C3: =الإعدادات!$C$8 -> المقرأة الأولى
A5: م | B5: اسم الطالب | C5: الحلقة | D5: 1 | E5: 2 | F5: 3 | G5: 4 | H5: 5 | I5: 6 | J5: 7 | K5: 8 | L5: 9 | M5: 10 | N5: 11 | O5: 12 | P5: 13 | Q5: 14 | R5: 15 | S5: 16 | T5: متوسط الإنجاز | U5: التقدير | V5: الحضور | W5: منها تأخر | X5: الغياب | Y5: الاعتذار | Z5: أوجه الحفظ | AA5: أوجه العرض | AB5: الأوجه المقروءة
A6: =IF($AC6="","",INDEX(الطلاب!$A$5:$A$44,$AC6)) -> 1 | B6: =IF($AC6="","",INDEX(الطلاب!$B$5:$B$44,$AC6)) -> غسان اليحيى | C6: =IF($AC6="","",INDEX(الطلاب!$D$5:$D$44,$AC6)) -> عبدالرحمن بن النعمان | D6: =IF($A6="","",IF(COUNTIFS(الإدخال!$A$5:$A$644,D$5,الإدخال!$D$5:$D$644,$A6,الإدخال!$F$5:$F$644,"غائب",الإدخال!$G$5:$G$644,"")>0,"غ",IF(COUNTIFS(الإدخال!$A$5:$A$644,D$5,الإدخال!$D$5:$D$644,$A6,الإدخال!$F$5:$F$644,"معتذر",الإدخال!$G$5:$G$644,"")>0,"ع",IF(SUMIFS(الإدخال!$P$5:$P$644,الإدخال!$A$5:$A$644,D$5,الإدخال!$D$5:$D$644,$A6)>0,SUMIFS(الإدخال!$O$5:$O$644,الإدخال!$A$5:$A$644,D$5,الإدخال!$D$5:$D$644,$A6)/100,"")))) -> 0.85 | E6: =IF($A6="","",IF(COUNTIFS(الإدخال!$A$5:$A$644,E$5,الإدخال!$D$5:$D$644,$A6,الإدخال!$F$5:$F$644,"غائب",الإدخال!$G$5:$G$644,"")>0,"غ",IF(COUNTIFS(الإدخال!$A$5:$A$644,E$5,الإدخال!$D$5:$D$644,$A6,الإدخال!$F$5:$F$644,"معتذر",الإدخال!$G$5:$G$644,"")>0,"ع",IF(SUMIFS(الإدخال!$P$5:$P$644,الإدخال!$A$5:$A$644,E$5,الإدخال!$D$5:$D$644,$A6)>0,SUMIFS(الإدخال!$O$5:$O$644,الإدخال!$A$5:$A$644,E$5,الإدخال!$D$5:$D$644,$A6)/100,"")))) -> 0.93 | F6: =IF($A6="","",IF(COUNTIFS(الإدخال!$A$5:$A$644,F$5,الإدخال!$D$5:$D$644,$A6,الإدخال!$F$5:$F$644,"غائب",الإدخال!$G$5:$G$644,"")>0,"غ",IF(COUNTIFS(الإدخال!$A$5:$A$644,F$5,الإدخال!$D$5:$D$644,$A6,الإدخال!$F$5:$F$644,"معتذر",الإدخال!$G$5:$G$644,"")>0,"ع",IF(SUMIFS(الإدخال!$P$5:$P$644,الإدخال!$A$5:$A$644,F$5,الإدخال!$D$5:$D$644,$A6)>0,SUMIFS(الإدخال!$O$5:$O$644,الإدخال!$A$5:$A$644,F$5,الإدخال!$D$5:$D$644,$A6)/100,"")))) | G6: =IF($A6="","",IF(COUNTIFS(الإدخال!$A$5:$A$644,G$5,الإدخال!$D$5:$D$644,$A6,الإدخال!$F$5:$F$644,"غائب",الإدخال!$G$5:$G$644,"")>0,"غ",IF(COUNTIFS(الإدخال!$A$5:$A$644,G$5,الإدخال!$D$5:$D$644,$A6,الإدخال!$F$5:$F$644,"معتذر",الإدخال!$G$5:$G$644,"")>0,"ع",IF(SUMIFS(الإدخال!$P$5:$P$644,الإدخال!$A$5:$A$644,G$5,الإدخال!$D$5:$D$644,$A6)>0,SUMIFS(الإدخال!$O$5:$O$644,الإدخال!$A$5:$A$644,G$5,الإدخال!$D$5:$D$644,$A6)/100,"")))) | H6: =IF($A6="","",IF(COUNTIFS(الإدخال!$A$5:$A$644,H$5,الإدخال!$D$5:$D$644,$A6,الإدخال!$F$5:$F$644,"غائب",الإدخال!$G$5:$G$644,"")>0,"غ",IF(COUNTIFS(الإدخال!$A$5:$A$644,H$5,الإدخال!$D$5:$D$644,$A6,الإدخال!$F$5:$F$644,"معتذر",الإدخال!$G$5:$G$644,"")>0,"ع",IF(SUMIFS(الإدخال!$P$5:$P$644,الإدخال!$A$5:$A$644,H$5,الإدخال!$D$5:$D$644,$A6)>0,SUMIFS(الإدخال!$O$5:$O$644,الإدخال!$A$5:$A$644,H$5,الإدخال!$D$5:$D$644,$A6)/100,"")))) | I6: =IF($A6="","",IF(COUNTIFS(الإدخال!$A$5:$A$644,I$5,الإدخال!$D$5:$D$644,$A6,الإدخال!$F$5:$F$644,"غائب",الإدخال!$G$5:$G$644,"")>0,"غ",IF(COUNTIFS(الإدخال!$A$5:$A$644,I$5,الإدخال!$D$5:$D$644,$A6,الإدخال!$F$5:$F$644,"معتذر",الإدخال!$G$5:$G$644,"")>0,"ع",IF(SUMIFS(الإدخال!$P$5:$P$644,الإدخال!$A$5:$A$644,I$5,الإدخال!$D$5:$D$644,$A6)>0,SUMIFS(الإدخال!$O$5:$O$644,الإدخال!$A$5:$A$644,I$5,الإدخال!$D$5:$D$644,$A6)/100,"")))) | J6: =IF($A6="","",IF(COUNTIFS(الإدخال!$A$5:$A$644,J$5,الإدخال!$D$5:$D$644,$A6,الإدخال!$F$5:$F$644,"غائب",الإدخال!$G$5:$G$644,"")>0,"غ",IF(COUNTIFS(الإدخال!$A$5:$A$644,J$5,الإدخال!$D$5:$D$644,$A6,الإدخال!$F$5:$F$644,"معتذر",الإدخال!$G$5:$G$644,"")>0,"ع",IF(SUMIFS(الإدخال!$P$5:$P$644,الإدخال!$A$5:$A$644,J$5,الإدخال!$D$5:$D$644,$A6)>0,SUMIFS(الإدخال!$O$5:$O$644,الإدخال!$A$5:$A$644,J$5,الإدخال!$D$5:$D$644,$A6)/100,"")))) | K6: =IF($A6="","",IF(COUNTIFS(الإدخال!$A$5:$A$644,K$5,الإدخال!$D$5:$D$644,$A6,الإدخال!$F$5:$F$644,"غائب",الإدخال!$G$5:$G$644,"")>0,"غ",IF(COUNTIFS(الإدخال!$A$5:$A$644,K$5,الإدخال!$D$5:$D$644,$A6,الإدخال!$F$5:$F$644,"معتذر",الإدخال!$G$5:$G$644,"")>0,"ع",IF(SUMIFS(الإدخال!$P$5:$P$644,الإدخال!$A$5:$A$644,K$5,الإدخال!$D$5:$D$644,$A6)>0,SUMIFS(الإدخال!$O$5:$O$644,الإدخال!$A$5:$A$644,K$5,الإدخال!$D$5:$D$644,$A6)/100,"")))) | ... S6: =IF($A6="","",IF(COUNTIFS(الإدخال!$A$5:$A$644,S$5,الإدخال!$D$5:$D$644,$A6,الإدخال!$F$5:$F$644,"غائب",الإدخال!$G$5:$G$644,"")>0,"غ",IF(COUNTIFS(الإدخال!$A$5:$A$644,S$5,الإدخال!$D$5:$D$644,$A6,الإدخال!$F$5:$F$644,"معتذر",الإدخال!$G$5:$G$644,"")>0,"ع",IF(SUMIFS(الإدخال!$P$5:$P$644,الإدخال!$A$5:$A$644,S$5,الإدخال!$D$5:$D$644,$A6)>0,SUMIFS(الإدخال!$O$5:$O$644,الإدخال!$A$5:$A$644,S$5,الإدخال!$D$5:$D$644,$A6)/100,"")))) | T6: =IF($A6="","",IFERROR(SUMIFS(الإدخال!$O$5:$O$644,الإدخال!$D$5:$D$644,$A6)/SUMIFS(الإدخال!$P$5:$P$644,الإدخال!$D$5:$D$644,$A6)/100,"")) -> 0.89 | U6: =IF(T6="","",IF(T6>=0.9,"ممتاز",IF(T6>=0.8,"جيد جدًا",IF(T6>=0.7,"جيد",IF(T6>=0.6,"مقبول","يحتاج متابعة"))))) -> جيد جدًا | V6: =IF($A6="","",SUMIFS(الإدخال!$N$5:$N$644,الإدخال!$D$5:$D$644,$A6)) -> 2 | W6: =IF($A6="","",COUNTIFS(الإدخال!$D$5:$D$644,$A6,الإدخال!$F$5:$F$644,"متأخر")) -> 0 | X6: =IF($A6="","",COUNTIFS(الإدخال!$D$5:$D$644,$A6,الإدخال!$F$5:$F$644,"غائب")) -> 0 | Y6: =IF($A6="","",COUNTIFS(الإدخال!$D$5:$D$644,$A6,الإدخال!$F$5:$F$644,"معتذر")) -> 0 | Z6: =IF($A6="","",SUMIFS(الإدخال!$H$5:$H$644,الإدخال!$D$5:$D$644,$A6,الإدخال!$N$5:$N$644,1)) -> 7 | AA6: =IF($A6="","",SUMIFS(الإدخال!$I$5:$I$644,الإدخال!$D$5:$D$644,$A6,الإدخال!$N$5:$N$644,1)) -> 40 | AB6: =IF($A6="","",SUMIFS(الإدخال!$J$5:$J$644,الإدخال!$D$5:$D$644,$A6,الإدخال!$N$5:$N$644,1)) -> 0 | AC6: =IFERROR(MATCH($C$3&"|1",الطلاب!$E$5:$E$44,0),"") -> 1
A7: =IF($AC7="","",INDEX(الطلاب!$A$5:$A$44,$AC7)) -> 2 | B7: =IF($AC7="","",INDEX(الطلاب!$B$5:$B$44,$AC7)) -> صالح الشريف | C7: =IF($AC7="","",INDEX(الطلاب!$D$5:$D$44,$AC7)) -> عبدالرحمن بن النعمان | D7: =IF($A7="","",IF(COUNTIFS(الإدخال!$A$5:$A$644,D$5,الإدخال!$D$5:$D$644,$A7,الإدخال!$F$5:$F$644,"غائب",الإدخال!$G$5:$G$644,"")>0,"غ",IF(COUNTIFS(الإدخال!$A$5:$A$644,D$5,الإدخال!$D$5:$D$644,$A7,الإدخال!$F$5:$F$644,"معتذر",الإدخال!$G$5:$G$644,"")>0,"ع",IF(SUMIFS(الإدخال!$P$5:$P$644,الإدخال!$A$5:$A$644,D$5,الإدخال!$D$5:$D$644,$A7)>0,SUMIFS(الإدخال!$O$5:$O$644,الإدخال!$A$5:$A$644,D$5,الإدخال!$D$5:$D$644,$A7)/100,"")))) -> 0.5 | E7: =IF($A7="","",IF(COUNTIFS(الإدخال!$A$5:$A$644,E$5,الإدخال!$D$5:$D$644,$A7,الإدخال!$F$5:$F$644,"غائب",الإدخال!$G$5:$G$644,"")>0,"غ",IF(COUNTIFS(الإدخال!$A$5:$A$644,E$5,الإدخال!$D$5:$D$644,$A7,الإدخال!$F$5:$F$644,"معتذر",الإدخال!$G$5:$G$644,"")>0,"ع",IF(SUMIFS(الإدخال!$P$5:$P$644,الإدخال!$A$5:$A$644,E$5,الإدخال!$D$5:$D$644,$A7)>0,SUMIFS(الإدخال!$O$5:$O$644,الإدخال!$A$5:$A$644,E$5,الإدخال!$D$5:$D$644,$A7)/100,"")))) -> 0.87 | F7: =IF($A7="","",IF(COUNTIFS(الإدخال!$A$5:$A$644,F$5,الإدخال!$D$5:$D$644,$A7,الإدخال!$F$5:$F$644,"غائب",الإدخال!$G$5:$G$644,"")>0,"غ",IF(COUNTIFS(الإدخال!$A$5:$A$644,F$5,الإدخال!$D$5:$D$644,$A7,الإدخال!$F$5:$F$644,"معتذر",الإدخال!$G$5:$G$644,"")>0,"ع",IF(SUMIFS(الإدخال!$P$5:$P$644,الإدخال!$A$5:$A$644,F$5,الإدخال!$D$5:$D$644,$A7)>0,SUMIFS(الإدخال!$O$5:$O$644,الإدخال!$A$5:$A$644,F$5,الإدخال!$D$5:$D$644,$A7)/100,"")))) | G7: =IF($A7="","",IF(COUNTIFS(الإدخال!$A$5:$A$644,G$5,الإدخال!$D$5:$D$644,$A7,الإدخال!$F$5:$F$644,"غائب",الإدخال!$G$5:$G$644,"")>0,"غ",IF(COUNTIFS(الإدخال!$A$5:$A$644,G$5,الإدخال!$D$5:$D$644,$A7,الإدخال!$F$5:$F$644,"معتذر",الإدخال!$G$5:$G$644,"")>0,"ع",IF(SUMIFS(الإدخال!$P$5:$P$644,الإدخال!$A$5:$A$644,G$5,الإدخال!$D$5:$D$644,$A7)>0,SUMIFS(الإدخال!$O$5:$O$644,الإدخال!$A$5:$A$644,G$5,الإدخال!$D$5:$D$644,$A7)/100,"")))) | H7: =IF($A7="","",IF(COUNTIFS(الإدخال!$A$5:$A$644,H$5,الإدخال!$D$5:$D$644,$A7,الإدخال!$F$5:$F$644,"غائب",الإدخال!$G$5:$G$644,"")>0,"غ",IF(COUNTIFS(الإدخال!$A$5:$A$644,H$5,الإدخال!$D$5:$D$644,$A7,الإدخال!$F$5:$F$644,"معتذر",الإدخال!$G$5:$G$644,"")>0,"ع",IF(SUMIFS(الإدخال!$P$5:$P$644,الإدخال!$A$5:$A$644,H$5,الإدخال!$D$5:$D$644,$A7)>0,SUMIFS(الإدخال!$O$5:$O$644,الإدخال!$A$5:$A$644,H$5,الإدخال!$D$5:$D$644,$A7)/100,"")))) | I7: =IF($A7="","",IF(COUNTIFS(الإدخال!$A$5:$A$644,I$5,الإدخال!$D$5:$D$644,$A7,الإدخال!$F$5:$F$644,"غائب",الإدخال!$G$5:$G$644,"")>0,"غ",IF(COUNTIFS(الإدخال!$A$5:$A$644,I$5,الإدخال!$D$5:$D$644,$A7,الإدخال!$F$5:$F$644,"معتذر",الإدخال!$G$5:$G$644,"")>0,"ع",IF(SUMIFS(الإدخال!$P$5:$P$644,الإدخال!$A$5:$A$644,I$5,الإدخال!$D$5:$D$644,$A7)>0,SUMIFS(الإدخال!$O$5:$O$644,الإدخال!$A$5:$A$644,I$5,الإدخال!$D$5:$D$644,$A7)/100,"")))) | J7: =IF($A7="","",IF(COUNTIFS(الإدخال!$A$5:$A$644,J$5,الإدخال!$D$5:$D$644,$A7,الإدخال!$F$5:$F$644,"غائب",الإدخال!$G$5:$G$644,"")>0,"غ",IF(COUNTIFS(الإدخال!$A$5:$A$644,J$5,الإدخال!$D$5:$D$644,$A7,الإدخال!$F$5:$F$644,"معتذر",الإدخال!$G$5:$G$644,"")>0,"ع",IF(SUMIFS(الإدخال!$P$5:$P$644,الإدخال!$A$5:$A$644,J$5,الإدخال!$D$5:$D$644,$A7)>0,SUMIFS(الإدخال!$O$5:$O$644,الإدخال!$A$5:$A$644,J$5,الإدخال!$D$5:$D$644,$A7)/100,"")))) | K7: =IF($A7="","",IF(COUNTIFS(الإدخال!$A$5:$A$644,K$5,الإدخال!$D$5:$D$644,$A7,الإدخال!$F$5:$F$644,"غائب",الإدخال!$G$5:$G$644,"")>0,"غ",IF(COUNTIFS(الإدخال!$A$5:$A$644,K$5,الإدخال!$D$5:$D$644,$A7,الإدخال!$F$5:$F$644,"معتذر",الإدخال!$G$5:$G$644,"")>0,"ع",IF(SUMIFS(الإدخال!$P$5:$P$644,الإدخال!$A$5:$A$644,K$5,الإدخال!$D$5:$D$644,$A7)>0,SUMIFS(الإدخال!$O$5:$O$644,الإدخال!$A$5:$A$644,K$5,الإدخال!$D$5:$D$644,$A7)/100,"")))) | ... S7: =IF($A7="","",IF(COUNTIFS(الإدخال!$A$5:$A$644,S$5,الإدخال!$D$5:$D$644,$A7,الإدخال!$F$5:$F$644,"غائب",الإدخال!$G$5:$G$644,"")>0,"غ",IF(COUNTIFS(الإدخال!$A$5:$A$644,S$5,الإدخال!$D$5:$D$644,$A7,الإدخال!$F$5:$F$644,"معتذر",الإدخال!$G$5:$G$644,"")>0,"ع",IF(SUMIFS(الإدخال!$P$5:$P$644,الإدخال!$A$5:$A$644,S$5,الإدخال!$D$5:$D$644,$A7)>0,SUMIFS(الإدخال!$O$5:$O$644,الإدخال!$A$5:$A$644,S$5,الإدخال!$D$5:$D$644,$A7)/100,"")))) | T7: =IF($A7="","",IFERROR(SUMIFS(الإدخال!$O$5:$O$644,الإدخال!$D$5:$D$644,$A7)/SUMIFS(الإدخال!$P$5:$P$644,الإدخال!$D$5:$D$644,$A7)/100,"")) -> 0.685 | U7: =IF(T7="","",IF(T7>=0.9,"ممتاز",IF(T7>=0.8,"جيد جدًا",IF(T7>=0.7,"جيد",IF(T7>=0.6,"مقبول","يحتاج متابعة"))))) -> مقبول | V7: =IF($A7="","",SUMIFS(الإدخال!$N$5:$N$644,الإدخال!$D$5:$D$644,$A7)) -> 2 | W7: =IF($A7="","",COUNTIFS(الإدخال!$D$5:$D$644,$A7,الإدخال!$F$5:$F$644,"متأخر")) -> 0 | X7: =IF($A7="","",COUNTIFS(الإدخال!$D$5:$D$644,$A7,الإدخال!$F$5:$F$644,"غائب")) -> 0 | Y7: =IF($A7="","",COUNTIFS(الإدخال!$D$5:$D$644,$A7,الإدخال!$F$5:$F$644,"معتذر")) -> 0 | Z7: =IF($A7="","",SUMIFS(الإدخال!$H$5:$H$644,الإدخال!$D$5:$D$644,$A7,الإدخال!$N$5:$N$644,1)) -> 1 | AA7: =IF($A7="","",SUMIFS(الإدخال!$I$5:$I$644,الإدخال!$D$5:$D$644,$A7,الإدخال!$N$5:$N$644,1)) -> 30 | AB7: =IF($A7="","",SUMIFS(الإدخال!$J$5:$J$644,الإدخال!$D$5:$D$644,$A7,الإدخال!$N$5:$N$644,1)) -> 0 | AC7: =IFERROR(MATCH($C$3&"|2",الطلاب!$E$5:$E$44,0),"") -> 2
A8: =IF($AC8="","",INDEX(الطلاب!$A$5:$A$44,$AC8)) -> 3 | B8: =IF($AC8="","",INDEX(الطلاب!$B$5:$B$44,$AC8)) -> فهد المشيقح | C8: =IF($AC8="","",INDEX(الطلاب!$D$5:$D$44,$AC8)) -> عبدالرحمن بن النعمان | D8: =IF($A8="","",IF(COUNTIFS(الإدخال!$A$5:$A$644,D$5,الإدخال!$D$5:$D$644,$A8,الإدخال!$F$5:$F$644,"غائب",الإدخال!$G$5:$G$644,"")>0,"غ",IF(COUNTIFS(الإدخال!$A$5:$A$644,D$5,الإدخال!$D$5:$D$644,$A8,الإدخال!$F$5:$F$644,"معتذر",الإدخال!$G$5:$G$644,"")>0,"ع",IF(SUMIFS(الإدخال!$P$5:$P$644,الإدخال!$A$5:$A$644,D$5,الإدخال!$D$5:$D$644,$A8)>0,SUMIFS(الإدخال!$O$5:$O$644,الإدخال!$A$5:$A$644,D$5,الإدخال!$D$5:$D$644,$A8)/100,"")))) -> 0.95 | E8: =IF($A8="","",IF(COUNTIFS(الإدخال!$A$5:$A$644,E$5,الإدخال!$D$5:$D$644,$A8,الإدخال!$F$5:$F$644,"غائب",الإدخال!$G$5:$G$644,"")>0,"غ",IF(COUNTIFS(الإدخال!$A$5:$A$644,E$5,الإدخال!$D$5:$D$644,$A8,الإدخال!$F$5:$F$644,"معتذر",الإدخال!$G$5:$G$644,"")>0,"ع",IF(SUMIFS(الإدخال!$P$5:$P$644,الإدخال!$A$5:$A$644,E$5,الإدخال!$D$5:$D$644,$A8)>0,SUMIFS(الإدخال!$O$5:$O$644,الإدخال!$A$5:$A$644,E$5,الإدخال!$D$5:$D$644,$A8)/100,"")))) -> 0.99 | F8: =IF($A8="","",IF(COUNTIFS(الإدخال!$A$5:$A$644,F$5,الإدخال!$D$5:$D$644,$A8,الإدخال!$F$5:$F$644,"غائب",الإدخال!$G$5:$G$644,"")>0,"غ",IF(COUNTIFS(الإدخال!$A$5:$A$644,F$5,الإدخال!$D$5:$D$644,$A8,الإدخال!$F$5:$F$644,"معتذر",الإدخال!$G$5:$G$644,"")>0,"ع",IF(SUMIFS(الإدخال!$P$5:$P$644,الإدخال!$A$5:$A$644,F$5,الإدخال!$D$5:$D$644,$A8)>0,SUMIFS(الإدخال!$O$5:$O$644,الإدخال!$A$5:$A$644,F$5,الإدخال!$D$5:$D$644,$A8)/100,"")))) | G8: =IF($A8="","",IF(COUNTIFS(الإدخال!$A$5:$A$644,G$5,الإدخال!$D$5:$D$644,$A8,الإدخال!$F$5:$F$644,"غائب",الإدخال!$G$5:$G$644,"")>0,"غ",IF(COUNTIFS(الإدخال!$A$5:$A$644,G$5,الإدخال!$D$5:$D$644,$A8,الإدخال!$F$5:$F$644,"معتذر",الإدخال!$G$5:$G$644,"")>0,"ع",IF(SUMIFS(الإدخال!$P$5:$P$644,الإدخال!$A$5:$A$644,G$5,الإدخال!$D$5:$D$644,$A8)>0,SUMIFS(الإدخال!$O$5:$O$644,الإدخال!$A$5:$A$644,G$5,الإدخال!$D$5:$D$644,$A8)/100,"")))) | H8: =IF($A8="","",IF(COUNTIFS(الإدخال!$A$5:$A$644,H$5,الإدخال!$D$5:$D$644,$A8,الإدخال!$F$5:$F$644,"غائب",الإدخال!$G$5:$G$644,"")>0,"غ",IF(COUNTIFS(الإدخال!$A$5:$A$644,H$5,الإدخال!$D$5:$D$644,$A8,الإدخال!$F$5:$F$644,"معتذر",الإدخال!$G$5:$G$644,"")>0,"ع",IF(SUMIFS(الإدخال!$P$5:$P$644,الإدخال!$A$5:$A$644,H$5,الإدخال!$D$5:$D$644,$A8)>0,SUMIFS(الإدخال!$O$5:$O$644,الإدخال!$A$5:$A$644,H$5,الإدخال!$D$5:$D$644,$A8)/100,"")))) | I8: =IF($A8="","",IF(COUNTIFS(الإدخال!$A$5:$A$644,I$5,الإدخال!$D$5:$D$644,$A8,الإدخال!$F$5:$F$644,"غائب",الإدخال!$G$5:$G$644,"")>0,"غ",IF(COUNTIFS(الإدخال!$A$5:$A$644,I$5,الإدخال!$D$5:$D$644,$A8,الإدخال!$F$5:$F$644,"معتذر",الإدخال!$G$5:$G$644,"")>0,"ع",IF(SUMIFS(الإدخال!$P$5:$P$644,الإدخال!$A$5:$A$644,I$5,الإدخال!$D$5:$D$644,$A8)>0,SUMIFS(الإدخال!$O$5:$O$644,الإدخال!$A$5:$A$644,I$5,الإدخال!$D$5:$D$644,$A8)/100,"")))) | J8: =IF($A8="","",IF(COUNTIFS(الإدخال!$A$5:$A$644,J$5,الإدخال!$D$5:$D$644,$A8,الإدخال!$F$5:$F$644,"غائب",الإدخال!$G$5:$G$644,"")>0,"غ",IF(COUNTIFS(الإدخال!$A$5:$A$644,J$5,الإدخال!$D$5:$D$644,$A8,الإدخال!$F$5:$F$644,"معتذر",الإدخال!$G$5:$G$644,"")>0,"ع",IF(SUMIFS(الإدخال!$P$5:$P$644,الإدخال!$A$5:$A$644,J$5,الإدخال!$D$5:$D$644,$A8)>0,SUMIFS(الإدخال!$O$5:$O$644,الإدخال!$A$5:$A$644,J$5,الإدخال!$D$5:$D$644,$A8)/100,"")))) | K8: =IF($A8="","",IF(COUNTIFS(الإدخال!$A$5:$A$644,K$5,الإدخال!$D$5:$D$644,$A8,الإدخال!$F$5:$F$644,"غائب",الإدخال!$G$5:$G$644,"")>0,"غ",IF(COUNTIFS(الإدخال!$A$5:$A$644,K$5,الإدخال!$D$5:$D$644,$A8,الإدخال!$F$5:$F$644,"معتذر",الإدخال!$G$5:$G$644,"")>0,"ع",IF(SUMIFS(الإدخال!$P$5:$P$644,الإدخال!$A$5:$A$644,K$5,الإدخال!$D$5:$D$644,$A8)>0,SUMIFS(الإدخال!$O$5:$O$644,الإدخال!$A$5:$A$644,K$5,الإدخال!$D$5:$D$644,$A8)/100,"")))) | ... S8: =IF($A8="","",IF(COUNTIFS(الإدخال!$A$5:$A$644,S$5,الإدخال!$D$5:$D$644,$A8,الإدخال!$F$5:$F$644,"غائب",الإدخال!$G$5:$G$644,"")>0,"غ",IF(COUNTIFS(الإدخال!$A$5:$A$644,S$5,الإدخال!$D$5:$D$644,$A8,الإدخال!$F$5:$F$644,"معتذر",الإدخال!$G$5:$G$644,"")>0,"ع",IF(SUMIFS(الإدخال!$P$5:$P$644,الإدخال!$A$5:$A$644,S$5,الإدخال!$D$5:$D$644,$A8)>0,SUMIFS(الإدخال!$O$5:$O$644,الإدخال!$A$5:$A$644,S$5,الإدخال!$D$5:$D$644,$A8)/100,"")))) | T8: =IF($A8="","",IFERROR(SUMIFS(الإدخال!$O$5:$O$644,الإدخال!$D$5:$D$644,$A8)/SUMIFS(الإدخال!$P$5:$P$644,الإدخال!$D$5:$D$644,$A8)/100,"")) -> 0.97 | U8: =IF(T8="","",IF(T8>=0.9,"ممتاز",IF(T8>=0.8,"جيد جدًا",IF(T8>=0.7,"جيد",IF(T8>=0.6,"مقبول","يحتاج متابعة"))))) -> ممتاز | V8: =IF($A8="","",SUMIFS(الإدخال!$N$5:$N$644,الإدخال!$D$5:$D$644,$A8)) -> 2 | W8: =IF($A8="","",COUNTIFS(الإدخال!$D$5:$D$644,$A8,الإدخال!$F$5:$F$644,"متأخر")) -> 0 | X8: =IF($A8="","",COUNTIFS(الإدخال!$D$5:$D$644,$A8,الإدخال!$F$5:$F$644,"غائب")) -> 0 | Y8: =IF($A8="","",COUNTIFS(الإدخال!$D$5:$D$644,$A8,الإدخال!$F$5:$F$644,"معتذر")) -> 0 | Z8: =IF($A8="","",SUMIFS(الإدخال!$H$5:$H$644,الإدخال!$D$5:$D$644,$A8,الإدخال!$N$5:$N$644,1)) -> 5 | AA8: =IF($A8="","",SUMIFS(الإدخال!$I$5:$I$644,الإدخال!$D$5:$D$644,$A8,الإدخال!$N$5:$N$644,1)) -> 52 | AB8: =IF($A8="","",SUMIFS(الإدخال!$J$5:$J$644,الإدخال!$D$5:$D$644,$A8,الإدخال!$N$5:$N$644,1)) -> 0 | AC8: =IFERROR(MATCH($C$3&"|3",الطلاب!$E$5:$E$44,0),"") -> 3
